Workbook

Sheet 1a-Performance
A1: PERFORMANCE ATTRIBUTE & REQUIREMENT DEFINITIONS
A2: VE Title : | B2: 포장두께
A4: Performance Attribute | B4: Definition
A5: 시공성
A6: 유지관리성
A7: 내구성
A8: 이용편의성
A9: 친환경성
A10: 배수성
A11: 교통안전성
A12: 민원성
A17: Performance Requirement | B17: Definition

Sheet 1b-Sub-Performance
A1: SUB-PERFORMANCE ATTRIBUTE DEFINITIONS
A2: ='1a-Performance'!A2:B2 -> VE Title : | B2: ='1a-Performance'!B2 -> 포장두께
A3: Performance Attribute #1 : | B3: ='1a-Performance'!A5 -> 시공성
A4: Sub-Performance Attribute | B4: Definition
A9: Performance Attribute #2 : | B9: ='1a-Performance'!A6 -> 유지관리성
A10: Sub-Performance Attribute | B10: Definition
A15: Performance Attribute #3 : | B15: ='1a-Performance'!A7 -> 내구성
A16: Sub-Performance Attribute | B16: Definition
A21: Performance Attribute #4 : | B21: ='1a-Performance'!A8 -> 이용편의성
A22: Sub-Performance Attribute | B22: Definition
A27: Performance Attribute #5 : | B27: ='1a-Performance'!A9 -> 친환경성
A28: Sub-Performance Attribute | B28: Definition
A33: Performance Attribute #6 : | B33: ='1a-Performance'!A10 -> 배수성
A34: Sub-Performance Attribute | B34: Definition
A39: Performance Attribute #7 : | B39: ='1a-Performance'!A11 -> 교통안전성
A40: Sub-Performance Attribute | B40: Definition
A45: Performance Attribute #8 : | B45: ='1a-Performance'!A12 -> 민원성
A46: Sub-Performance Attribute | B46: Definition

Sheet 2a-Attribute Scales (1)
A1: PERFORMANCE ATTRIBUTE SCALES
A2: ='1a-Performance'!A2:B2 -> VE Title : | C2: ='1a-Performance'!B2 -> 포장두께
A3: Perfomance Attributes
A4: Rating | B4: ='1a-Performance'!A5 -> 시공성 | C4: ='1a-Performance'!A6 -> 유지관리성 | D4: ='1a-Performance'!A7 -> 내구성 | E4: ='1a-Performance'!A8 -> 이용편의성 | F4: ='1a-Performance'!A9 -> 친환경성 | G4: ='1a-Performance'!A10 -> 배수성 | H4: ='1a-Performance'!A11 -> 교통안전성 | I4: ='1a-Performance'!A12 -> 민원성
A5: 10 | B5: Alternative Concept is extremely preferred.
A6: 9 | B6: Alternative Concept is very strongly preferred.
A7: 8 | B7: Alternative Concept is strongly preferred.
A8: 7 | B8: Alternative Concept is moderately preferred.
A9: 6 | B9: Alternative Concept is slightly preferred.
A10: 5 | B10: Concepts are equally preferred.
A11: 4 | B11: Baseline Concept is slightly preferred.
A12: 3 | B12: Baseline Concept is moderately preferred.
A13: 2 | B13: Baseline Concept is strongly preferred.
A14: 1 | B14: Baseline Concept is very strongly preferred.
A15: 0 | B15: Baseline Concept is extremely preferred.
A17: Baseline Concept Evaluation
B18: =B4 -> 시공성 | C18: =C4 -> 유지관리성 | D18: =D4 -> 내구성 | E18: =E4 -> 이용편의성 | F18: =F4 -> 친환경성 | G18: =G4 -> 배수성 | H18: =H4 -> 교통안전성 | I18: =I4 -> 민원성
A19: Evaluation Rationale

Sheet 2b-Attribute Scales (2)
A1: PERFORMANCE ATTRIBUTE SCALES
A2: ='1a-Performance'!A2:B2 -> VE Title : | C2: ='1a-Performance'!B2 -> 포장두께
A3: Perfomance Attributes
A4: Rating
A5: 10 | B5: Alternative Concept is extremely preferred.
A6: 9 | B6: Alternative Concept is very strongly preferred.
A7: 8 | B7: Alternative Concept is strongly preferred.
A8: 7 | B8: Alternative Concept is moderately preferred.
A9: 6 | B9: Alternative Concept is slightly preferred.
A10: 5 | B10: Concepts are equally preferred.
A11: 4 | B11: Baseline Concept is slightly preferred.
A12: 3 | B12: Baseline Concept is moderately preferred.
A13: 2 | B13: Baseline Concept is strongly preferred.
A14: 1 | B14: Baseline Concept is very strongly preferred.
A15: 0 | B15: Baseline Concept is extremely preferred.
A17: Baseline Concept Evaluation
B18: =B4 -> 0 | C18: =C4 -> 0 | D18: =D4 -> 0 | E18: =E4 -> 0 | F18: =F4 -> 0 | G18: =G4 -> 0 | H18: =H4 -> 0 | I18: =I4 -> 0
A19: Evaluation Rationale

Sheet 2c-Attribute Scales (3)
A1: PERFORMANCE ATTRIBUTE SCALES
A2: ='1a-Performance'!A2:B2 -> VE Title : | C2: ='1a-Performance'!B2 -> 포장두께
A3: Perfomance Attributes
A4: Rating
A5: 10 | B5: >50% reduction in amount
A6: 9 | B6: 36~50% reduction in amount
A7: 8 | B7: 21~35% reduction in amount
A8: 7 | B8: 11~20% reduction in amount
A9: 6 | B9: 1~10% reduction in amount
A10: 5 | B10: Current amount
A11: 4 | B11: 1~10% increase in amount
A12: 3 | B12: 11~20% increase in amount
A13: 2 | B13: 21~35% increase in amount
A14: 1 | B14: 36~50% increase in amount
A15: 0 | B15: >50% increase in amount
A17: Baseline Concept Evaluation
B18: =B4 -> 0 | C18: =C4 -> 0 | D18: =D4 -> 0 | E18: =E4 -> 0 | F18: =F4 -> 0 | G18: =G4 -> 0 | H18: =H4 -> 0 | I18: =I4 -> 0
A19: Evaluation Rationale

Sheet 2d-Attribute Scales (4)
A1: PERFORMANCE ATTRIBUTE SCALES
A2: ='1a-Performance'!A2:B2 -> VE Title : | C2: ='1a-Performance'!B2 -> 포장두께
A3: Perfomance Attributes
A4: Rating
A5: 10 | B5: >50% reduction in amount | F5: >50% increase in amount
A6: 9 | B6: 36~50% reduction in amount | F6: 36~50% increase in amount
A7: 8 | B7: 21~35% reduction in amount | F7: 21~35% increase in amount
A8: 7 | B8: 11~20% reduction in amount | F8: 11~20% increase in amount
A9: 6 | B9: 1~10% reduction in amount | F9: 1~10% increase in amount
A10: 5 | B10: Current amount | F10: Current amount
A11: 4 | B11: 1~10% increase in amount | F11: 1~10% reduction in amount
A12: 3 | B12: 11~20% increase in amount | F12: 11~20% reduction in amount
A13: 2 | B13: 21~35% increase in amount | F13: 21~35% reduction in amount
A14: 1 | B14: 36~50% increase in amount | F14: 36~50% reduction in amount
A15: 0 | B15: >50% increase in amount | F15: >50% reduction in amount
A17: Baseline Concept Evaluation
B18: =B4 -> 0 | C18: =C4 -> 0 | D18: =D4 -> 0 | E18: =E4 -> 0 | F18: =F4 -> 0 | G18: =G4 -> 0 | H18: =H4 -> 0 | I18: =I4 -> 0
A19: Evaluation Rationale

Sheet 2e-Attribute Scales (5)
A1: PERFORMANCE ATTRIBUTE SCALES
A2: ='1a-Performance'!A2:B2 -> VE Title : | C2: ='1a-Performance'!B2 -> 포장두께
A3: Perfomance Attributes
A4: Rating
A5: 10 | B5: LOS "A" : Volume/Capacity = 0.0~0.3 ; Free flow - excellent operation
A6: 9 | B6: LOS "B" : Volume/Capacity = 0.31~0.48 ; Stable flow - very/good operation
A7: 8 | B7: LOS "C" : Volume/Capacity = 0.49~0.64 ; Stable flow - good operation
A8: 7 | B8: LOS "D" : Volume/Capacity = 0.65~0.80 ; Approaching unstable flow - fair operation
A9: 6 | B9: LOS "E" : Volume/Capacity = 0.81~0.90 ; Unstable flow - poor operation
A10: 5
A11: 4 | B11: LOS "F" : Volume/Capacity = 0.91~1.05 ; Traffic congestion for 15 minutes to 1 hour
A12: 3 | B12: LOS "F" : Volume/Capacity = 1.06~1.20 ; Traffic congestion for 1 to 2 hour
A13: 2 | B13: LOS "F" : Volume/Capacity = 1.21~1.34 ; Traffic congestion for 2 to 3 hour
A14: 1 | B14: LOS "F" : Volume/Capacity = 1.35 or more ; Traffic congestion for more than 3 hours
A15: 0
A17: Baseline Concept Evaluation
B18: =B4 -> 0 | C18: =C4 -> 0 | D18: =D4 -> 0 | E18: =E4 -> 0 | F18: =F4 -> 0 | G18: =G4 -> 0 | H18: =H4 -> 0 | I18: =I4 -> 0
A19: Evaluation Rationale

Sheet 3a-Attribute Rating(A)
A1: PERFORMANCE ATTRIBUTE RATING(METHOD-A)
A2: ='1a-Performance'!A2 -> VE Title : | C2: ='1a-Performance'!B2 -> 포장두께
A3: A. 입력값 평균법
A4: A-1. Pairwise Comparison Matrices
A5: 평 가 항 목 | C5: 1 | D5: 2 | E5: 3 | F5: 4 | G5: 5 | H5: 6 | I5: 7 | J5: 8 | L5: 행곱 | M5: N | N5: Eigen Vector | O5: Priority Vector | P5: 확정치(%)
A6: 1 | B6: ='1a-Performance'!A5 -> 시공성 | C6: 1 | D6: =GEOMEAN('3c-PCM#1'!D6) -> 1 | E6: =GEOMEAN('3c-PCM#1'!E6) -> 1.5 | F6: =GEOMEAN('3c-PCM#1'!F6) -> 1 | G6: =GEOMEAN('3c-PCM#1'!G6) -> 1.5 | H6: =GEOMEAN('3c-PCM#1'!H6) -> 2 | I6: =GEOMEAN('3c-PCM#1'!I6) -> 2 | J6: =GEOMEAN('3c-PCM#1'!J6) -> 1 | L6: =PRODUCT(C6:J6) -> 9 | M6: =IF($J$6<>"",8,(IF($I$6<>"",7,(IF($H$6<>"",6,5))))) -> 8 | N6: =L6^(1/M6) -> 1.316074 | O6: =N6/$N$14 -> 0.16271659 | P6: =ROUND(O6,3) -> 0.163
A7: 2 | B7: ='1a-Performance'!A6 -> 유지관리성 | C7: =1/D6 -> 1 | D7: 1 | E7: =GEOMEAN('3c-PCM#1'!E7) -> 1 | F7: =GEOMEAN('3c-PCM#1'!F7) -> 1 | G7: =GEOMEAN('3c-PCM#1'!G7) -> 1.5 | H7: =GEOMEAN('3c-PCM#1'!H7) -> 1 | I7: =GEOMEAN('3c-PCM#1'!I7) -> 2 | J7: =GEOMEAN('3c-PCM#1'!J7) -> 1 | L7: =PRODUCT(C7:J7) -> 3 | M7: =IF($J$6<>"",8,(IF($I$6<>"",7,(IF($H$6<>"",6,5))))) -> 8 | N7: =L7^(1/M7) -> 1.1472027 | O7: =N7/$N$14 -> 0.1418377 | P7: =ROUND(O7,3) -> 0.142
A8: 3 | B8: ='1a-Performance'!A7 -> 내구성 | C8: =1/E6 -> 0.66666667 | D8: =1/E7 -> 1 | E8: 1 | F8: =GEOMEAN('3c-PCM#1'!F8) -> 1.5 | G8: =GEOMEAN('3c-PCM#1'!G8) -> 1 | H8: =GEOMEAN('3c-PCM#1'!H8) -> 1 | I8: =GEOMEAN('3c-PCM#1'!I8) -> 1.5 | J8: =GEOMEAN('3c-PCM#1'!J8) -> 1 | L8: =PRODUCT(C8:J8) -> 1.5 | M8: =IF($J$6<>"",8,(IF($I$6<>"",7,(IF($H$6<>"",6,5))))) -> 8 | N8: =L8^(1/M8) -> 1.0519895 | O8: =N8/$N$14 -> 0.13006574 | P8: =ROUND(O8,3)-0.001 -> 0.129
A9: 4 | B9: ='1a-Performance'!A8 -> 이용편의성 | C9: =1/F6 -> 1 | D9: =1/F7 -> 1 | E9: =1/F8 -> 0.66666667 | F9: 1 | G9: =GEOMEAN('3c-PCM#1'!G9) -> 1 | H9: =GEOMEAN('3c-PCM#1'!H9) -> 1 | I9: =GEOMEAN('3c-PCM#1'!I9) -> 1 | J9: =GEOMEAN('3c-PCM#1'!J9) -> 1 | L9: =PRODUCT(C9:J9) -> 0.66666667 | M9: =IF($J$6<>"",8,(IF($I$6<>"",7,(IF($H$6<>"",6,5))))) -> 8 | N9: =L9^(1/M9) -> 0.95057982 | O9: =N9/$N$14 -> 0.11752767 | P9: =ROUND(O9,3)-0.001 -> 0.117
A10: 5 | B10: ='1a-Performance'!A9 -> 친환경성 | C10: =1/G6 -> 0.66666667 | D10: =1/G7 -> 0.66666667 | E10: =1/G8 -> 1 | F10: =1/G9 -> 1 | G10: 1 | H10: =GEOMEAN('3c-PCM#1'!H10) -> 0.7 | I10: =GEOMEAN('3c-PCM#1'!I10) -> 0.5 | J10: =GEOMEAN('3c-PCM#1'!J10) -> 1 | L10: =PRODUCT(C10:J10) -> 0.15555556 | M10: =IF($J$6<>"",8,(IF($I$6<>"",7,(IF($H$6<>"",6,5))))) -> 8 | N10: =L10^(1/M10) -> 0.79247522 | O10: =N10/$N$14 -> 0.097979949 | P10: =ROUND(O10,3) -> 0.098
A11: 6 | B11: ='1a-Performance'!A10 -> 배수성 | C11: =1/H6 -> 0.5 | D11: =1/H7 -> 1 | E11: =1/H8 -> 1 | F11: =1/H9 -> 1 | G11: =1/H10 -> 1.4285714 | H11: 1 | I11: =GEOMEAN('3c-PCM#1'!I11) -> 0.5 | J11: =GEOMEAN('3c-PCM#1'!J11) -> 1 | L11: =PRODUCT(C11:J11) -> 0.35714286 | M11: =IF($J$6<>"",8,(IF($I$6<>"",7,(IF($H$6<>"",6,5))))) -> 8 | N11: =L11^(1/M11) -> 0.87923556 | O11: =N11/$N$14 -> 0.10870681 | P11: =ROUND(O11,3) -> 0.109
A12: 7 | B12: ='1a-Performance'!A11 -> 교통안전성 | C12: =1/I6 -> 0.5 | D12: =1/I7 -> 0.5 | E12: =1/I8 -> 0.66666667 | F12: =1/I9 -> 1 | G12: =1/I10 -> 2 | H12: =1/I11 -> 2 | I12: 1 | J12: =GEOMEAN('3c-PCM#1'!J12) -> 1 | L12: =PRODUCT(C12:J12) -> 0.66666667 | M12: =IF($J$6<>"",8,(IF($I$6<>"",7,(IF($H$6<>"",6,5))))) -> 8 | N12: =L12^(1/M12) -> 0.95057982 | O12: =N12/$N$14 -> 0.11752767 | P12: =ROUND(O12,3) -> 0.118
A13: 8 | B13: ='1a-Performance'!A12 -> 민원성 | C13: =1/J6 -> 1 | D13: =1/J7 -> 1 | E13: =1/J8 -> 1 | F13: =1/J9 -> 1 | G13: =1/J10 -> 1 | H13: =1/J11 -> 1 | I13: =1/J12 -> 1 | J13: 1 | L13: =PRODUCT(C13:J13) -> 1 | M13: =IF($J$6<>"",8,(IF($I$6<>"",7,(IF($H$6<>"",6,5))))) -> 8 | N13: =L13^(1/M13) -> 1 | O13: =N13/$N$14 -> 0.12363787 | P13: =ROUND(O13,3) -> 0.124
A14: 열(Column)합 | C14: =SUM(C6:C13) -> 6.3333333 | D14: =SUM(D6:D13) -> 7.1666667 | E14: =SUM(E6:E13) -> 7.8333333 | F14: =SUM(F6:F13) -> 8.5 | G14: =SUM(G6:G13) -> 10.428571 | H14: =SUM(H6:H13) -> 9.7 | I14: =SUM(I6:I13) -> 9.5 | J14: =SUM(J6:J13) -> 8 | L14: SUM | N14: =SUM(N6:N13) -> 8.0881366 | O14: =SUM(O6:O13) -> 1 | P14: =SUM(P6:P13) -> 1
A15: A-2. Confidence Index(CI)
A16: ▶ λmax = | C16: =MMULT(C14:J14,O6:O13) -> 8.2467382 | D16: ☜ Pairwise Comparison Matrices의 열합행렬(1행×8열)과 Priority Veoctor(8행×1열)의 행렬곱
A17: ▶ CI = | C17: =(C16-M6)/(M6-1) -> 0.035248314 | D17: ☜ CI = (λmax - N) / (N-1)
A18: ▶ CR = | C18: =C17/(HLOOKUP(M6,C19:J20,2,TRUE)) -> 0.024998804 | D18: ☜ CR = CI / RI | F18: =IF(C18<=0.1,"∴O.K","∴N.G") -> ∴O.K
B19: N | C19: 3 | D19: 4 | E19: 5 | F19: 6 | G19: 7 | H19: 8 | I19: 9 | J19: 10
B20: RI | C20: 0.58 | D20: 0.9 | E20: 1.12 | F20: 1.24 | G20: 1.32 | H20: 1.41 | I20: 1.45 | J20: 1.51
A22: B. 결과치 평균법
A23: 평 가 항 목 | C23: 1 | D23: 2 | E23: 3 | F23: 4 | G23: 5 | H23: 6 | I23: 7 | J23: 평균
A24: 1 | B24: =B6 -> 시공성 | C24: ='3c-PCM#1'!P6 -> 0.163 | D24: =#REF! -> #REF! | E24: =#REF! -> #REF! | F24: =#REF! -> #REF! | G24: =#REF! -> #REF! | J24: =AVERAGE(C24:I24) -> #REF!
A25: 2 | B25: =B7 -> 유지관리성 | C25: ='3c-PCM#1'!P7 -> 0.142 | D25: =#REF! -> #REF! | E25: =#REF! -> #REF! | F25: =#REF! -> #REF! | G25: =#REF! -> #REF! | J25: =AVERAGE(C25:I25) -> #REF!
A26: 3 | B26: =B8 -> 내구성 | C26: ='3c-PCM#1'!P8 -> 0.13 | D26: =#REF! -> #REF! | E26: =#REF! -> #REF! | F26: =#REF! -> #REF! | G26: =#REF! -> #REF! | J26: =AVERAGE(C26:I26) -> #REF!
A27: 4 | B27: =B9 -> 이용편의성 | C27: ='3c-PCM#1'!P9 -> 0.118 | D27: =#REF! -> #REF! | E27: =#REF! -> #REF! | F27: =#REF! -> #REF! | G27: =#REF! -> #REF! | J27: =AVERAGE(C27:I27) -> #REF!
A28: 5 | B28: =B10 -> 친환경성 | C28: ='3c-PCM#1'!P10 -> 0.098 | D28: =#REF! -> #REF! | E28: =#REF! -> #REF! | F28: =#REF! -> #REF! | G28: =#REF! -> #REF! | J28: =AVERAGE(C28:I28) -> #REF!
A29: 6 | B29: =B11 -> 배수성 | C29: ='3c-PCM#1'!P11 -> 0.109 | D29: =#REF! -> #REF! | E29: =#REF! -> #REF! | F29: =#REF! -> #REF! | G29: =#REF! -> #REF! | J29: =AVERAGE(C29:I29) -> #REF!
A30: 7 | B30: =B12 -> 교통안전성 | C30: ='3c-PCM#1'!P12 -> 0.118 | D30: =#REF! -> #REF! | E30: =#REF! -> #REF! | F30: =#REF! -> #REF! | G30: =#REF! -> #REF! | J30: =AVERAGE(C30:I30) -> #REF!
A31: 8 | B31: =B13 -> 민원성 | C31: ='3c-PCM#1'!P13 -> 0.124 | D31: =#REF! -> #REF! | E31: =#REF! -> #REF! | F31: =#REF! -> #REF! | G31: =#REF! -> #REF! | J31: =AVERAGE(C31:I31) -> #REF!
A32: 합 계 | C32: =SUM(C24:C31) -> 1.002 | D32: =SUM(D24:D31) -> #REF! | E32: =SUM(E24:E31) -> #REF! | F32: =SUM(F24:F31) -> #REF! | G32: =SUM(G24:G31) -> #REF! | J32: =SUM(J24:J31) -> #REF!

Sheet 3b-Attribute Rating(B)
A1: PERFORMANCE ATTRIBUTE RATING(METHOD-B)
A2: ='1a-Performance'!A2 -> VE Title : | C2: ='1a-Performance'!B2 -> 포장두께
A3: A. 가중치 결정 설문결과(절대값 적용) | G3: 본 과업에서는 적용하지 않음
A4: No | B4: 평가항목 | C4: 전문가 7인 설문 응답지 | L4: 설문 평균 | M4: VE팀 평균 | N4: 전체평균 | P4: COV
C5: 1 | D5: 2 | E5: 3 | F5: 4 | G5: 5 | H5: 6 | I5: 7 | J5: 8 | K5: 9 | N5: 계산치 | O5: 조정치
A6: 1 | B6: ='3a-Attribute Rating(A)'!B6 -> 시공성 | C6: ='3c-PCM#1'!Q6 -> 9 | D6: 7 | E6: 6 | F6: 7 | G6: 8 | H6: 8 | I6: 8 | J6: 8 | K6: 8 | L6: =AVERAGE(C6:I6) -> 7.5714286 | M6: 8 | N6: =(L6*0.7+M6*0.3) -> 7.7 | O6: =ROUND(N6,0) -> 8 | P6: =SQRT(VAR(C6:I6))/O6 -> 0.12198751
A7: 2 | B7: ='3a-Attribute Rating(A)'!B7 -> 유지관리성 | C7: ='3c-PCM#1'!Q7 -> 8 | D7: 9 | E7: 8 | F7: 9 | G7: 8 | H7: 8 | I7: 9 | J7: 9 | K7: 9 | L7: =AVERAGE(C7:I7) -> 8.4285714 | M7: 8.6 | N7: =(L7*0.7+M7*0.3) -> 8.48 | O7: =ROUND(N7,0) -> 8 | P7: =SQRT(VAR(C7:I7))/O7 -> 0.06681531
A8: 3 | B8: ='3a-Attribute Rating(A)'!B8 -> 내구성 | C8: ='3c-PCM#1'!Q8 -> 7 | D8: 8 | E8: 7 | F8: 6 | G8: 6 | H8: 8 | I8: 8 | J8: 8 | K8: 8 | L8: =AVERAGE(C8:I8) -> 7.1428571 | M8: 8.3 | N8: =(L8*0.7+M8*0.3) -> 7.49 | O8: =ROUND(N8,0) -> 7 | P8: =SQRT(VAR(C8:I8))/O8 -> 0.12853363
A9: 4 | B9: ='3a-Attribute Rating(A)'!B9 -> 이용편의성 | C9: ='3c-PCM#1'!Q9 -> 7 | D9: 8 | E9: 8 | F9: 8 | G9: 9 | H9: 8 | I9: 9 | J9: 9 | K9: 9 | L9: =AVERAGE(C9:I9) -> 8.1428571 | M9: 8.7 | N9: =(L9*0.7+M9*0.3) -> 8.31 | O9: =ROUND(N9,0) -> 8 | P9: =SQRT(VAR(C9:I9))/O9 -> 0.086258195
A10: 5 | B10: ='3a-Attribute Rating(A)'!B10 -> 친환경성 | C10: ='3c-PCM#1'!Q10 -> 5 | D10: 8 | E10: 9 | F10: 8 | G10: 7 | H10: 8 | I10: 9 | J10: 9 | K10: 9 | L10: =AVERAGE(C10:I10) -> 7.7142857 | M10: 8.6 | N10: =(L10*0.7+M10*0.3) -> 7.98 | O10: =ROUND(N10,0) -> 8 | P10: =SQRT(VAR(C10:I10))/O10 -> 0.17251639
A11: 6 | B11: ='3a-Attribute Rating(A)'!B11 -> 배수성 | C11: ='3c-PCM#1'!Q11 -> 6 | D11: 8 | E11: 9 | F11: 8 | G11: 8 | H11: 9 | I11: 8 | J11: 8 | K11: 8 | L11: =AVERAGE(C11:I11) -> 8 | M11: 8.8 | N11: =(L11*0.7+M11*0.3) -> 8.24 | O11: =ROUND(N11,0) -> 8 | P11: =SQRT(VAR(C11:I11))/O11 -> 0.125
A12: 7 | B12: ='3a-Attribute Rating(A)'!B12 -> 교통안전성
A13: 8 | B13: ='3a-Attribute Rating(A)'!B13 -> 민원성
A14: B. Pairwise Comparison Matrices
A15: 평 가 항 목 | C15: 1 | D15: 2 | E15: 3 | F15: 4 | G15: 5 | H15: 6 | I15: 7 | J15: 8 | L15: 행곱 | M15: N | N15: Eigen Vector | O15: Priority Vector | P15: 확정치(%)
A16: 1 | B16: =B6 -> 시공성 | C16: 1 | D16: =IF(O6>O7, MAX(O6,O7)-MIN(O6,O7)+1, 1/(MAX(O6,O7)-MIN(O6,O7)+1)) -> 1 | E16: =IF(O6>O8, MAX(O6,O8)-MIN(O6,O8)+1, 1/(MAX(O6,O8)-MIN(O6,O8)+1)) -> 2 | F16: =IF(O6>O9, MAX(O6,O9)-MIN(O6,O9)+1, 1/(MAX(O6,O9)-MIN(O6,O9)+1)) -> 1 | G16: =IF(O6>O10, MAX(O6,O10)-MIN(O6,O10)+1, 1/(MAX(O6,O10)-MIN(O6,O10)+1)) -> 1 | H16: =IF(O6>O11, MAX(O6,O11)-MIN(O6,O11)+1, 1/(MAX(O6,O11)-MIN(O6,O11)+1)) -> 1 | L16: =PRODUCT(C16:J16) -> 2 | M16: =$H$15 -> 6 | N16: =L16^(1/M16) -> 1.122462 | O16: =N16/$N$24 -> 0.18181818 | P16: =ROUND(O16,3) -> 0.182
A17: 2 | B17: =B7 -> 유지관리성 | C17: =1/D16 -> 1 | D17: 1 | E17: =IF(O7>O8, MAX(O7,O8)-MIN(O7,O8)+1, 1/(MAX(O7,O8)-MIN(O7,O8)+1)) -> 2 | F17: =IF(O7>O9, MAX(O7,O9)-MIN(O7,O9)+1, 1/(MAX(O7,O9)-MIN(O7,O9)+1)) -> 1 | G17: =IF(O7>O10, MAX(O7,O10)-MIN(O7,O10)+1, 1/(MAX(O7,O10)-MIN(O7,O10)+1)) -> 1 | H17: =IF(O7>O11, MAX(O7,O11)-MIN(O7,O11)+1, 1/(MAX(O7,O11)-MIN(O7,O11)+1)) -> 1 | L17: =PRODUCT(C17:J17) -> 2 | M17: =$H$15 -> 6 | N17: =L17^(1/M17) -> 1.122462 | O17: =N17/$N$24 -> 0.18181818 | P17: =ROUND(O17,3) -> 0.182
A18: 3 | B18: =B8 -> 내구성 | C18: =1/E16 -> 0.5 | D18: =1/E17 -> 0.5 | E18: 1 | F18: =IF(O8>O9, MAX(O8,O9)-MIN(O8,O9)+1, 1/(MAX(O8,O9)-MIN(O8,O9)+1)) -> 0.5 | G18: =IF(O8>O10, MAX(O8,O10)-MIN(O8,O10)+1, 1/(MAX(O8,O10)-MIN(O8,O10)+1)) -> 0.5 | H18: =IF(O8>O11, MAX(O8,O11)-MIN(O8,O11)+1, 1/(MAX(O8,O11)-MIN(O8,O11)+1)) -> 0.5 | L18: =PRODUCT(C18:J18) -> 0.03125 | M18: =$H$15 -> 6 | N18: =L18^(1/M18) -> 0.56123102 | O18: =N18/$N$24 -> 0.090909091 | P18: =ROUND(O18,3) -> 0.091
A19: 4 | B19: =B9 -> 이용편의성 | C19: =1/F16 -> 1 | D19: =1/F17 -> 1 | E19: =1/F18 -> 2 | F19: 1 | G19: =IF(O9>O10, MAX(O9,O10)-MIN(O9,O10)+1, 1/(MAX(O9,O10)-MIN(O9,O10)+1)) -> 1 | H19: =IF(O9>O11, MAX(O9,O11)-MIN(O9,O11)+1, 1/(MAX(O9,O11)-MIN(O9,O11)+1)) -> 1 | L19: =PRODUCT(C19:J19) -> 2 | M19: =$H$15 -> 6 | N19: =L19^(1/M19) -> 1.122462 | O19: =N19/$N$24 -> 0.18181818 | P19: =ROUND(O19,3) -> 0.182
A20: 5 | B20: =B10 -> 친환경성 | C20: =1/G16 -> 1 | D20: =1/G17 -> 1 | E20: =1/G18 -> 2 | F20: =1/G19 -> 1 | G20: 1 | H20: =IF(O10>O11, MAX(O10,O11)-MIN(O10,O11)+1, 1/(MAX(O10,O11)-MIN(O10,O11)+1)) -> 1 | L20: =PRODUCT(C20:J20) -> 2 | M20: =$H$15 -> 6 | N20: =L20^(1/M20) -> 1.122462 | O20: =N20/$N$24 -> 0.18181818 | P20: =ROUND(O20,3) -> 0.182
A21: 6 | B21: =B11 -> 배수성 | C21: =1/H16 -> 1 | D21: =1/H17 -> 1 | E21: =1/H18 -> 2 | F21: =1/H19 -> 1 | G21: =1/H20 -> 1 | H21: 1 | L21: =PRODUCT(C21:J21) -> 2 | M21: =$H$15 -> 6 | N21: =L21^(1/M21) -> 1.122462 | O21: =N21/$N$24 -> 0.18181818 | P21: =ROUND(O21,3) -> 0.182
A22: 7 | B22: =B12 -> 교통안전성
A23: 8 | B23: =B13 -> 민원성
A24: 열(Column)합 | C24: =SUM(C16:C23) -> 5.5 | D24: =SUM(D16:D23) -> 5.5 | E24: =SUM(E16:E23) -> 11 | F24: =SUM(F16:F23) -> 5.5 | G24: =SUM(G16:G23) -> 5.5 | H24: =SUM(H16:H23) -> 5.5 | L24: SUM | N24: =SUM(N16:N23) -> 6.1735413 | O24: =SUM(O16:O23) -> 1 | P24: =SUM(P16:P23) -> 1.001
A25: C. Confidence Index(CI)
A26: C-1. λmax = | C26: =MMULT(C24:H24,O16:O21) -> 6 | D26: ☜ Pairwise Comparison Matrices의 열합행렬(1행×8열)과 Priority Veoctor(8행×1열)의 행렬곱
A27: C-2. CI = | C27: =(C26-M16)/(M16-1) -> 0 | D27: ☜ CI = (λmax - N) / (N-1) | H27: C-3. CR = | J27: =C27/(HLOOKUP(M16,C28:J29,2,TRUE)) -> 0 | K27: ☜ CR = CI / RI
B28: N | C28: 3 | D28: 4 | E28: 5 | F28: 6 | G28: 7 | H28: 8 | I28: 9 | J28: 10
B29: RI | C29: 0.58 | D29: 0.9 | E29: 1.12 | F29: 1.24 | G29: 1.32 | H29: 1.41 | I29: 1.45 | J29: 1.51

Sheet 3c-PCM#1
A1: PERFORMANCE ATTRIBUTE RATING(PCM#1)
A2: ='1a-Performance'!A2 -> VE Title : | C2: ='1a-Performance'!B2 -> 포장두께
A3: A. Pairwise Comparison Matrices | G3: (설문자 : VE전문가)
A5: 평 가 항 목 | C5: 1 | D5: 2 | E5: 3 | F5: 4 | G5: 5 | H5: 6 | I5: 7 | J5: 8 | L5: 행곱 | M5: N | N5: Eigen Vector | O5: Priority Vector | P5: 확정치(%) | Q5: 절대값
A6: 1 | B6: ='3a-Attribute Rating(A)'!B6 -> 시공성 | C6: 1 | D6: 1 | E6: 1.5 | F6: 1 | G6: 1.5 | H6: 2 | I6: 2 | J6: 1 | L6: =PRODUCT(C6:J6) -> 9 | M6: =IF($J$6<>"",8,(IF($I$6<>"",7,(IF($H$6<>"",6,5))))) -> 8 | N6: =L6^(1/M6) -> 1.316074 | O6: =N6/$N$14 -> 0.16271659 | P6: =ROUND(O6,3) -> 0.163 | Q6: =ROUND(O6/MAX($O$6:$O$13)*9,0) -> 9
A7: 2 | B7: ='3a-Attribute Rating(A)'!B7 -> 유지관리성 | C7: =1/D6 -> 1 | D7: 1 | E7: 1 | F7: 1 | G7: 1.5 | H7: 1 | I7: 2 | J7: 1 | L7: =PRODUCT(C7:J7) -> 3 | M7: =IF($J$6<>"",8,(IF($I$6<>"",7,(IF($H$6<>"",6,5))))) -> 8 | N7: =L7^(1/M7) -> 1.1472027 | O7: =N7/$N$14 -> 0.1418377 | P7: =ROUND(O7,3) -> 0.142 | Q7: =ROUND(O7/MAX($O$6:$O$13)*9,0) -> 8
A8: 3 | B8: ='3a-Attribute Rating(A)'!B8 -> 내구성 | C8: =1/E6 -> 0.66666667 | D8: =1/E7 -> 1 | E8: 1 | F8: 1.5 | G8: 1 | H8: 1 | I8: 1.5 | J8: 1 | L8: =PRODUCT(C8:J8) -> 1.5 | M8: =IF($J$6<>"",8,(IF($I$6<>"",7,(IF($H$6<>"",6,5))))) -> 8 | N8: =L8^(1/M8) -> 1.0519895 | O8: =N8/$N$14 -> 0.13006574 | P8: =ROUND(O8,3) -> 0.13 | Q8: =ROUND(O8/MAX($O$6:$O$13)*9,0) -> 7
A9: 4 | B9: ='3a-Attribute Rating(A)'!B9 -> 이용편의성 | C9: =1/F6 -> 1 | D9: =1/F7 -> 1 | E9: =1/F8 -> 0.66666667 | F9: 1 | G9: 1 | H9: 1 | I9: 1 | J9: 1 | L9: =PRODUCT(C9:J9) -> 0.66666667 | M9: =IF($J$6<>"",8,(IF($I$6<>"",7,(IF($H$6<>"",6,5))))) -> 8 | N9: =L9^(1/M9) -> 0.95057982 | O9: =N9/$N$14 -> 0.11752767 | P9: =ROUND(O9,3) -> 0.118 | Q9: =ROUND(O9/MAX($O$6:$O$13)*9,0) -> 7
A10: 5 | B10: ='3a-Attribute Rating(A)'!B10 -> 친환경성 | C10: =1/G6 -> 0.66666667 | D10: =1/G7 -> 0.66666667 | E10: =1/G8 -> 1 | F10: =1/G9 -> 1 | G10: 1 | H10: 0.7 | I10: 0.5 | J10: 1 | L10: =PRODUCT(C10:J10) -> 0.15555556 | M10: =IF($J$6<>"",8,(IF($I$6<>"",7,(IF($H$6<>"",6,5))))) -> 8 | N10: =L10^(1/M10) -> 0.79247522 | O10: =N10/$N$14 -> 0.097979949 | P10: =ROUND(O10,3) -> 0.098 | Q10: =ROUND(O10/MAX($O$6:$O$13)*9,0) -> 5
A11: 6 | B11: ='3a-Attribute Rating(A)'!B11 -> 배수성 | C11: =1/H6 -> 0.5 | D11: =1/H7 -> 1 | E11: =1/H8 -> 1 | F11: =1/H9 -> 1 | G11: =1/H10 -> 1.4285714 | H11: 1 | I11: 0.5 | J11: 1 | L11: =PRODUCT(C11:J11) -> 0.35714286 | M11: =IF($J$6<>"",8,(IF($I$6<>"",7,(IF($H$6<>"",6,5))))) -> 8 | N11: =L11^(1/M11) -> 0.87923556 | O11: =N11/$N$14 -> 0.10870681 | P11: =ROUND(O11,3) -> 0.109 | Q11: =ROUND(O11/MAX($O$6:$O$13)*9,0) -> 6
A12: 7 | B12: ='3a-Attribute Rating(A)'!B12 -> 교통안전성 | C12: =1/I6 -> 0.5 | D12: =1/I7 -> 0.5 | E12: =1/I8 -> 0.66666667 | F12: =1/I9 -> 1 | G12: =1/I10 -> 2 | H12: =1/I11 -> 2 | I12: 1 | J12: 1 | L12: =PRODUCT(C12:J12) -> 0.66666667 | M12: =IF($J$6<>"",8,(IF($I$6<>"",7,(IF($H$6<>"",6,5))))) -> 8 | N12: =L12^(1/M12) -> 0.95057982 | O12: =N12/$N$14 -> 0.11752767 | P12: =ROUND(O12,3) -> 0.118 | Q12: =ROUND(O12/MAX($O$6:$O$13)*9,0) -> 7
A13: 8 | B13: ='3a-Attribute Rating(A)'!B13 -> 민원성 | C13: =1/J6 -> 1 | D13: =1/J7 -> 1 | E13: =1/J8 -> 1 | F13: =1/J9 -> 1 | G13: =1/J10 -> 1 | H13: =1/J11 -> 1 | I13: =1/J12 -> 1 | J13: 1 | L13: =PRODUCT(C13:J13) -> 1 | M13: =IF($J$6<>"",8,(IF($I$6<>"",7,(IF($H$6<>"",6,5))))) -> 8 | N13: =L13^(1/M13) -> 1 | O13: =N13/$N$14 -> 0.12363787 | P13: =ROUND(O13,3) -> 0.124 | Q13: =ROUND(O13/MAX($O$6:$O$13)*9,0) -> 7
A14: 열(Column)합 | C14: =SUM(C6:C13) -> 6.3333333 | D14: =SUM(D6:D13) -> 7.1666667 | E14: =SUM(E6:E13) -> 7.8333333 | F14: =SUM(F6:F13) -> 8.5 | G14: =SUM(G6:G13) -> 10.428571 | H14: =SUM(H6:H13) -> 9.7 | I14: =SUM(I6:I13) -> 9.5 | J14: =SUM(J6:J13) -> 8 | L14: SUM | N14: =SUM(N6:N13) -> 8.0881366 | O14: =SUM(O6:O13) -> 1 | P14: =SUM(P6:P13) -> 1.002
A16: B. Confidence Index(CI)
A17: B-1. λmax = | C17: =MMULT(C14:J14,O6:O13) -> 8.2467382 | D17: ☜ Pairwise Comparison Matrices의 열합행렬(1행×8열)과 Priority Veoctor(8행×1열)의 행렬곱
A18: B-2. CI = | C18: =(C17-M6)/(M6-1) -> 0.035248314 | D18: ☜ CI = (λmax - N) / (N-1)
A19: B-3. CR = | C19: =C18/(HLOOKUP(M6,C20:J21,2,TRUE)) -> 0.024998804 | D19: ☜ CR = CI / RI | F19: =IF(C19<=0.1,"∴O.K","∴N.G") -> ∴O.K
B20: N | C20: 3 | D20: 4 | E20: 5 | F20: 6 | G20: 7 | H20: 8 | I20: 9 | J20: 10
B21: RI | C21: 0.58 | D21: 0.9 | E21: 1.12 | F21: 1.24 | G21: 1.32 | H21: 1.41 | I21: 1.45 | J21: 1.51

Sheet 3d-PCM#2
A1: PERFORMANCE ATTRIBUTE RATING(PCM#2)
A2: ='1a-Performance'!A2 -> VE Title : | C2: ='1a-Performance'!B2 -> 포장두께
A3: A. Pairwise Comparison Matrices | G3: (설문자 : 시공전문가)
A5: 평 가 항 목 | C5: 1 | D5: 2 | E5: 3 | F5: 4 | G5: 5 | H5: 6 | I5: 7 | J5: 8 | L5: 행곱 | M5: N | N5: Eigen Vector | O5: Priority Vector | P5: 확정치(%) | Q5: 절대값
A6: 1 | B6: ='3a-Attribute Rating(A)'!B6 -> 시공성 | C6: 1 | D6: 1 | E6: 2 | F6: 2 | G6: 2 | H6: 3 | I6: 2 | J6: 3 | L6: =PRODUCT(C6:J6) -> 144 | M6: =IF($J$6<>"",8,(IF($I$6<>"",7,(IF($H$6<>"",6,5))))) -> 8 | N6: =L6^(1/M6) -> 1.8612097 | O6: =N6/$N$14 -> 0.21856255 | P6: =ROUND(O6,3) -> 0.219 | Q6: =ROUND(O6/MAX($O$6:$O$13)*9,0) -> 9
A7: 2 | B7: ='3a-Attribute Rating(A)'!B7 -> 유지관리성 | C7: =1/D6 -> 1 | D7: 1 | E7: 2 | F7: 1 | G7: 2 | H7: 2 | I7: 1 | J7: 2 | L7: =PRODUCT(C7:J7) -> 16 | M7: =IF($J$6<>"",8,(IF($I$6<>"",7,(IF($H$6<>"",6,5))))) -> 8 | N7: =L7^(1/M7) -> 1.4142136 | O7: =N7/$N$14 -> 0.16607162 | P7: =ROUND(O7,3) -> 0.166 | Q7: =ROUND(O7/MAX($O$6:$O$13)*9,0) -> 7
A8: 3 | B8: ='3a-Attribute Rating(A)'!B8 -> 내구성 | C8: =1/E6 -> 0.5 | D8: =1/E7 -> 0.5 | E8: 1 | F8: 1 | G8: 1 | H8: 2 | I8: 1 | J8: 2 | L8: =PRODUCT(C8:J8) -> 1 | M8: =IF($J$6<>"",8,(IF($I$6<>"",7,(IF($H$6<>"",6,5))))) -> 8 | N8: =L8^(1/M8) -> 1 | O8: =N8/$N$14 -> 0.11743037 | P8: =ROUND(O8,3) -> 0.117 | Q8: =ROUND(O8/MAX($O$6:$O$13)*9,0) -> 5
A9: 4 | B9: ='3a-Attribute Rating(A)'!B9 -> 이용편의성 | C9: =1/F6 -> 0.5 | D9: =1/F7 -> 1 | E9: =1/F8 -> 1 | F9: 1 | G9: 1 | H9: 1 | I9: 1 | J9: 1 | L9: =PRODUCT(C9:J9) -> 0.5 | M9: =IF($J$6<>"",8,(IF($I$6<>"",7,(IF($H$6<>"",6,5))))) -> 8 | N9: =L9^(1/M9) -> 0.91700404 | O9: =N9/$N$14 -> 0.10768413 | P9: =ROUND(O9,3) -> 0.108 | Q9: =ROUND(O9/MAX($O$6:$O$13)*9,0) -> 4
A10: 5 | B10: ='3a-Attribute Rating(A)'!B10 -> 친환경성 | C10: =1/G6 -> 0.5 | D10: =1/G7 -> 0.5 | E10: =1/G8 -> 1 | F10: =1/G9 -> 1 | G10: 1 | H10: 2 | I10: 1 | J10: 2 | L10: =PRODUCT(C10:J10) -> 1 | M10: =IF($J$6<>"",8,(IF($I$6<>"",7,(IF($H$6<>"",6,5))))) -> 8 | N10: =L10^(1/M10) -> 1 | O10: =N10/$N$14 -> 0.11743037 | P10: =ROUND(O10,3) -> 0.117 | Q10: =ROUND(O10/MAX($O$6:$O$13)*9,0) -> 5
A11: 6 | B11: ='3a-Attribute Rating(A)'!B11 -> 배수성 | C11: =1/H6 -> 0.33333333 | D11: =1/H7 -> 0.5 | E11: =1/H8 -> 0.5 | F11: =1/H9 -> 1 | G11: =1/H10 -> 0.5 | H11: 1 | I11: =1/2 -> 0.5 | J11: 1 | L11: =PRODUCT(C11:J11) -> 0.020833333 | M11: =IF($J$6<>"",8,(IF($I$6<>"",7,(IF($H$6<>"",6,5))))) -> 8 | N11: =L11^(1/M11) -> 0.61637476 | O11: =N11/$N$14 -> 0.072381117 | P11: =ROUND(O11,3) -> 0.072 | Q11: =ROUND(O11/MAX($O$6:$O$13)*9,0) -> 3
A12: 7 | B12: ='3a-Attribute Rating(A)'!B12 -> 교통안전성 | C12: =1/I6 -> 0.5 | D12: =1/I7 -> 1 | E12: =1/I8 -> 1 | F12: =1/I9 -> 1 | G12: =1/I10 -> 1 | H12: =1/I11 -> 2 | I12: 1 | J12: 2 | L12: =PRODUCT(C12:J12) -> 2 | M12: =IF($J$6<>"",8,(IF($I$6<>"",7,(IF($H$6<>"",6,5))))) -> 8 | N12: =L12^(1/M12) -> 1.0905077 | O12: =N12/$N$14 -> 0.12805873 | P12: =ROUND(O12,3) -> 0.128 | Q12: =ROUND(O12/MAX($O$6:$O$13)*9,0) -> 5
A13: 8 | B13: ='3a-Attribute Rating(A)'!B13 -> 민원성 | C13: =1/J6 -> 0.33333333 | D13: =1/J7 -> 0.5 | E13: =1/J8 -> 0.5 | F13: =1/J9 -> 1 | G13: =1/J10 -> 0.5 | H13: =1/J11 -> 1 | I13: =1/J12 -> 0.5 | J13: 1 | L13: =PRODUCT(C13:J13) -> 0.020833333 | M13: =IF($J$6<>"",8,(IF($I$6<>"",7,(IF($H$6<>"",6,5))))) -> 8 | N13: =L13^(1/M13) -> 0.61637476 | O13: =N13/$N$14 -> 0.072381117 | P13: =ROUND(O13,3) -> 0.072 | Q13: =ROUND(O13/MAX($O$6:$O$13)*9,0) -> 3
A14: 열(Column)합 | C14: =SUM(C6:C13) -> 4.6666667 | D14: =SUM(D6:D13) -> 6 | E14: =SUM(E6:E13) -> 9 | F14: =SUM(F6:F13) -> 9 | G14: =SUM(G6:G13) -> 9 | H14: =SUM(H6:H13) -> 14 | I14: =SUM(I6:I13) -> 8 | J14: =SUM(J6:J13) -> 14 | L14: SUM | N14: =SUM(N6:N13) -> 8.5156846 | O14: =SUM(O6:O13) -> 1 | P14: =SUM(P6:P13) -> 0.999
A16: B. Confidence Index(CI)
A17: B-1. λmax = | C17: =MMULT(C14:J14,O6:O13) -> 8.1504332 | D17: ☜ Pairwise Comparison Matrices의 열합행렬(1행×8열)과 Priority Veoctor(8행×1열)의 행렬곱
A18: B-2. CI = | C18: =(C17-M6)/(M6-1) -> 0.021490456 | D18: ☜ CI = (λmax - N) / (N-1)
A19: B-3. CR = | C19: =C18/(HLOOKUP(M6,C20:J21,2,TRUE)) -> 0.015241458 | D19: ☜ CR = CI / RI | F19: =IF(C19<=0.1,"∴O.K","∴N.G") -> ∴O.K
B20: N | C20: 3 | D20: 4 | E20: 5 | F20: 6 | G20: 7 | H20: 8 | I20: 9 | J20: 10
B21: RI | C21: 0.58 | D21: 0.9 | E21: 1.12 | F21: 1.24 | G21: 1.32 | H21: 1.41 | I21: 1.45 | J21: 1.51

Sheet 3e-PCM#3
A1: PERFORMANCE ATTRIBUTE RATING(PCM#3)
A2: ='1a-Performance'!A2 -> VE Title : | C2: ='1a-Performance'!B2 -> 포장두께
A3: A. Pairwise Comparison Matrices | G3: (설문자 : 시공전문가)
A5: 평 가 항 목 | C5: 1 | D5: 2 | E5: 3 | F5: 4 | G5: 5 | H5: 6 | I5: 7 | J5: 8 | L5: 행곱 | M5: N | N5: Eigen Vector | O5: Priority Vector | P5: 확정치(%) | Q5: 절대값
A6: 1 | B6: ='3a-Attribute Rating(A)'!B6 -> 시공성 | C6: 1 | D6: 1 | E6: 2 | F6: 2 | G6: 2 | H6: 3 | I6: 2 | J6: 3 | L6: =PRODUCT(C6:J6) -> 144 | M6: =IF($J$6<>"",8,(IF($I$6<>"",7,(IF($H$6<>"",6,5))))) -> 8 | N6: =L6^(1/M6) -> 1.8612097 | O6: =N6/$N$14 -> 0.21856255 | P6: =ROUND(O6,3) -> 0.219 | Q6: =ROUND(O6/MAX($O$6:$O$13)*9,0) -> 9
A7: 2 | B7: ='3a-Attribute Rating(A)'!B7 -> 유지관리성 | C7: =1/D6 -> 1 | D7: 1 | E7: 2 | F7: 1 | G7: 2 | H7: 2 | I7: 1 | J7: 2 | L7: =PRODUCT(C7:J7) -> 16 | M7: =IF($J$6<>"",8,(IF($I$6<>"",7,(IF($H$6<>"",6,5))))) -> 8 | N7: =L7^(1/M7) -> 1.4142136 | O7: =N7/$N$14 -> 0.16607162 | P7: =ROUND(O7,3) -> 0.166 | Q7: =ROUND(O7/MAX($O$6:$O$13)*9,0) -> 7
A8: 3 | B8: ='3a-Attribute Rating(A)'!B8 -> 내구성 | C8: =1/E6 -> 0.5 | D8: =1/E7 -> 0.5 | E8: 1 | F8: 1 | G8: 1 | H8: 2 | I8: 1 | J8: 2 | L8: =PRODUCT(C8:J8) -> 1 | M8: =IF($J$6<>"",8,(IF($I$6<>"",7,(IF($H$6<>"",6,5))))) -> 8 | N8: =L8^(1/M8) -> 1 | O8: =N8/$N$14 -> 0.11743037 | P8: =ROUND(O8,3) -> 0.117 | Q8: =ROUND(O8/MAX($O$6:$O$13)*9,0) -> 5
A9: 4 | B9: ='3a-Attribute Rating(A)'!B9 -> 이용편의성 | C9: =1/F6 -> 0.5 | D9: =1/F7 -> 1 | E9: =1/F8 -> 1 | F9: 1 | G9: 1 | H9: 1 | I9: 1 | J9: 1 | L9: =PRODUCT(C9:J9) -> 0.5 | M9: =IF($J$6<>"",8,(IF($I$6<>"",7,(IF($H$6<>"",6,5))))) -> 8 | N9: =L9^(1/M9) -> 0.91700404 | O9: =N9/$N$14 -> 0.10768413 | P9: =ROUND(O9,3) -> 0.108 | Q9: =ROUND(O9/MAX($O$6:$O$13)*9,0) -> 4
A10: 5 | B10: ='3a-Attribute Rating(A)'!B10 -> 친환경성 | C10: =1/G6 -> 0.5 | D10: =1/G7 -> 0.5 | E10: =1/G8 -> 1 | F10: =1/G9 -> 1 | G10: 1 | H10: 2 | I10: 1 | J10: 2 | L10: =PRODUCT(C10:J10) -> 1 | M10: =IF($J$6<>"",8,(IF($I$6<>"",7,(IF($H$6<>"",6,5))))) -> 8 | N10: =L10^(1/M10) -> 1 | O10: =N10/$N$14 -> 0.11743037 | P10: =ROUND(O10,3) -> 0.117 | Q10: =ROUND(O10/MAX($O$6:$O$13)*9,0) -> 5
A11: 6 | B11: ='3a-Attribute Rating(A)'!B11 -> 배수성 | C11: =1/H6 -> 0.33333333 | D11: =1/H7 -> 0.5 | E11: =1/H8 -> 0.5 | F11: =1/H9 -> 1 | G11: =1/H10 -> 0.5 | H11: 1 | I11: =1/2 -> 0.5 | J11: 1 | L11: =PRODUCT(C11:J11) -> 0.020833333 | M11: =IF($J$6<>"",8,(IF($I$6<>"",7,(IF($H$6<>"",6,5))))) -> 8 | N11: =L11^(1/M11) -> 0.61637476 | O11: =N11/$N$14 -> 0.072381117 | P11: =ROUND(O11,3) -> 0.072 | Q11: =ROUND(O11/MAX($O$6:$O$13)*9,0) -> 3
A12: 7 | B12: ='3a-Attribute Rating(A)'!B12 -> 교통안전성 | C12: =1/I6 -> 0.5 | D12: =1/I7 -> 1 | E12: =1/I8 -> 1 | F12: =1/I9 -> 1 | G12: =1/I10 -> 1 | H12: =1/I11 -> 2 | I12: 1 | J12: 2 | L12: =PRODUCT(C12:J12) -> 2 | M12: =IF($J$6<>"",8,(IF($I$6<>"",7,(IF($H$6<>"",6,5))))) -> 8 | N12: =L12^(1/M12) -> 1.0905077 | O12: =N12/$N$14 -> 0.12805873 | P12: =ROUND(O12,3) -> 0.128 | Q12: =ROUND(O12/MAX($O$6:$O$13)*9,0) -> 5
A13: 8 | B13: ='3a-Attribute Rating(A)'!B13 -> 민원성 | C13: =1/J6 -> 0.33333333 | D13: =1/J7 -> 0.5 | E13: =1/J8 -> 0.5 | F13: =1/J9 -> 1 | G13: =1/J10 -> 0.5 | H13: =1/J11 -> 1 | I13: =1/J12 -> 0.5 | J13: 1 | L13: =PRODUCT(C13:J13) -> 0.020833333 | M13: =IF($J$6<>"",8,(IF($I$6<>"",7,(IF($H$6<>"",6,5))))) -> 8 | N13: =L13^(1/M13) -> 0.61637476 | O13: =N13/$N$14 -> 0.072381117 | P13: =ROUND(O13,3) -> 0.072 | Q13: =ROUND(O13/MAX($O$6:$O$13)*9,0) -> 3
A14: 열(Column)합 | C14: =SUM(C6:C13) -> 4.6666667 | D14: =SUM(D6:D13) -> 6 | E14: =SUM(E6:E13) -> 9 | F14: =SUM(F6:F13) -> 9 | G14: =SUM(G6:G13) -> 9 | H14: =SUM(H6:H13) -> 14 | I14: =SUM(I6:I13) -> 8 | J14: =SUM(J6:J13) -> 14 | L14: SUM | N14: =SUM(N6:N13) -> 8.5156846 | O14: =SUM(O6:O13) -> 1 | P14: =SUM(P6:P13) -> 0.999
A16: B. Confidence Index(CI)
A17: B-1. λmax = | C17: =MMULT(C14:J14,O6:O13) -> 8.1504332 | D17: ☜ Pairwise Comparison Matrices의 열합행렬(1행×8열)과 Priority Veoctor(8행×1열)의 행렬곱
A18: B-2. CI = | C18: =(C17-M6)/(M6-1) -> 0.021490456 | D18: ☜ CI = (λmax - N) / (N-1)
A19: B-3. CR = | C19: =C18/(HLOOKUP(M6,C20:J21,2,TRUE)) -> 0.015241458 | D19: ☜ CR = CI / RI | F19: =IF(C19<=0.1,"∴O.K","∴N.G") -> ∴O.K
B20: N | C20: 3 | D20: 4 | E20: 5 | F20: 6 | G20: 7 | H20: 8 | I20: 9 | J20: 10
B21: RI | C21: 0.58 | D21: 0.9 | E21: 1.12 | F21: 1.24 | G21: 1.32 | H21: 1.41 | I21: 1.45 | J21: 1.51

Sheet 3f-PCM#4
A1: PERFORMANCE ATTRIBUTE RATING(PCM#4)
A2: ='1a-Performance'!A2 -> VE Title : | C2: ='1a-Performance'!B2 -> 포장두께
A3: A. Pairwise Comparison Matrices | G3: (설문자 : 시공전문가)
A5: 평 가 항 목 | C5: 1 | D5: 2 | E5: 3 | F5: 4 | G5: 5 | H5: 6 | I5: 7 | J5: 8 | L5: 행곱 | M5: N | N5: Eigen Vector | O5: Priority Vector | P5: 확정치(%) | Q5: 절대값
A6: 1 | B6: ='3a-Attribute Rating(A)'!B6 -> 시공성 | C6: 1 | D6: 1 | E6: 2 | F6: 2 | G6: 2 | H6: 3 | I6: 2 | J6: 3 | L6: =PRODUCT(C6:J6) -> 144 | M6: =IF($J$6<>"",8,(IF($I$6<>"",7,(IF($H$6<>"",6,5))))) -> 8 | N6: =L6^(1/M6) -> 1.8612097 | O6: =N6/$N$14 -> 0.21856255 | P6: =ROUND(O6,3) -> 0.219 | Q6: =ROUND(O6/MAX($O$6:$O$13)*9,0) -> 9
A7: 2 | B7: ='3a-Attribute Rating(A)'!B7 -> 유지관리성 | C7: =1/D6 -> 1 | D7: 1 | E7: 2 | F7: 1 | G7: 2 | H7: 2 | I7: 1 | J7: 2 | L7: =PRODUCT(C7:J7) -> 16 | M7: =IF($J$6<>"",8,(IF($I$6<>"",7,(IF($H$6<>"",6,5))))) -> 8 | N7: =L7^(1/M7) -> 1.4142136 | O7: =N7/$N$14 -> 0.16607162 | P7: =ROUND(O7,3) -> 0.166 | Q7: =ROUND(O7/MAX($O$6:$O$13)*9,0) -> 7
A8: 3 | B8: ='3a-Attribute Rating(A)'!B8 -> 내구성 | C8: =1/E6 -> 0.5 | D8: =1/E7 -> 0.5 | E8: 1 | F8: 1 | G8: 1 | H8: 2 | I8: 1 | J8: 2 | L8: =PRODUCT(C8:J8) -> 1 | M8: =IF($J$6<>"",8,(IF($I$6<>"",7,(IF($H$6<>"",6,5))))) -> 8 | N8: =L8^(1/M8) -> 1 | O8: =N8/$N$14 -> 0.11743037 | P8: =ROUND(O8,3) -> 0.117 | Q8: =ROUND(O8/MAX($O$6:$O$13)*9,0) -> 5
A9: 4 | B9: ='3a-Attribute Rating(A)'!B9 -> 이용편의성 | C9: =1/F6 -> 0.5 | D9: =1/F7 -> 1 | E9: =1/F8 -> 1 | F9: 1 | G9: 1 | H9: 1 | I9: 1 | J9: 1 | L9: =PRODUCT(C9:J9) -> 0.5 | M9: =IF($J$6<>"",8,(IF($I$6<>"",7,(IF($H$6<>"",6,5))))) -> 8 | N9: =L9^(1/M9) -> 0.91700404 | O9: =N9/$N$14 -> 0.10768413 | P9: =ROUND(O9,3) -> 0.108 | Q9: =ROUND(O9/MAX($O$6:$O$13)*9,0) -> 4
A10: 5 | B10: ='3a-Attribute Rating(A)'!B10 -> 친환경성 | C10: =1/G6 -> 0.5 | D10: =1/G7 -> 0.5 | E10: =1/G8 -> 1 | F10: =1/G9 -> 1 | G10: 1 | H10: 2 | I10: 1 | J10: 2 | L10: =PRODUCT(C10:J10) -> 1 | M10: =IF($J$6<>"",8,(IF($I$6<>"",7,(IF($H$6<>"",6,5))))) -> 8 | N10: =L10^(1/M10) -> 1 | O10: =N10/$N$14 -> 0.11743037 | P10: =ROUND(O10,3) -> 0.117 | Q10: =ROUND(O10/MAX($O$6:$O$13)*9,0) -> 5
A11: 6 | B11: ='3a-Attribute Rating(A)'!B11 -> 배수성 | C11: =1/H6 -> 0.33333333 | D11: =1/H7 -> 0.5 | E11: =1/H8 -> 0.5 | F11: =1/H9 -> 1 | G11: =1/H10 -> 0.5 | H11: 1 | I11: =1/2 -> 0.5 | J11: 1 | L11: =PRODUCT(C11:J11) -> 0.020833333 | M11: =IF($J$6<>"",8,(IF($I$6<>"",7,(IF($H$6<>"",6,5))))) -> 8 | N11: =L11^(1/M11) -> 0.61637476 | O11: =N11/$N$14 -> 0.072381117 | P11: =ROUND(O11,3) -> 0.072 | Q11: =ROUND(O11/MAX($O$6:$O$13)*9,0) -> 3
A12: 7 | B12: ='3a-Attribute Rating(A)'!B12 -> 교통안전성 | C12: =1/I6 -> 0.5 | D12: =1/I7 -> 1 | E12: =1/I8 -> 1 | F12: =1/I9 -> 1 | G12: =1/I10 -> 1 | H12: =1/I11 -> 2 | I12: 1 | J12: 2 | L12: =PRODUCT(C12:J12) -> 2 | M12: =IF($J$6<>"",8,(IF($I$6<>"",7,(IF($H$6<>"",6,5))))) -> 8 | N12: =L12^(1/M12) -> 1.0905077 | O12: =N12/$N$14 -> 0.12805873 | P12: =ROUND(O12,3) -> 0.128 | Q12: =ROUND(O12/MAX($O$6:$O$13)*9,0) -> 5
A13: 8 | B13: ='3a-Attribute Rating(A)'!B13 -> 민원성 | C13: =1/J6 -> 0.33333333 | D13: =1/J7 -> 0.5 | E13: =1/J8 -> 0.5 | F13: =1/J9 -> 1 | G13: =1/J10 -> 0.5 | H13: =1/J11 -> 1 | I13: =1/J12 -> 0.5 | J13: 1 | L13: =PRODUCT(C13:J13) -> 0.020833333 | M13: =IF($J$6<>"",8,(IF($I$6<>"",7,(IF($H$6<>"",6,5))))) -> 8 | N13: =L13^(1/M13) -> 0.61637476 | O13: =N13/$N$14 -> 0.072381117 | P13: =ROUND(O13,3) -> 0.072 | Q13: =ROUND(O13/MAX($O$6:$O$13)*9,0) -> 3
A14: 열(Column)합 | C14: =SUM(C6:C13) -> 4.6666667 | D14: =SUM(D6:D13) -> 6 | E14: =SUM(E6:E13) -> 9 | F14: =SUM(F6:F13) -> 9 | G14: =SUM(G6:G13) -> 9 | H14: =SUM(H6:H13) -> 14 | I14: =SUM(I6:I13) -> 8 | J14: =SUM(J6:J13) -> 14 | L14: SUM | N14: =SUM(N6:N13) -> 8.5156846 | O14: =SUM(O6:O13) -> 1 | P14: =SUM(P6:P13) -> 0.999
A16: B. Confidence Index(CI)
A17: B-1. λmax = | C17: =MMULT(C14:J14,O6:O13) -> 8.1504332 | D17: ☜ Pairwise Comparison Matrices의 열합행렬(1행×8열)과 Priority Veoctor(8행×1열)의 행렬곱
A18: B-2. CI = | C18: =(C17-M6)/(M6-1) -> 0.021490456 | D18: ☜ CI = (λmax - N) / (N-1)
A19: B-3. CR = | C19: =C18/(HLOOKUP(M6,C20:J21,2,TRUE)) -> 0.015241458 | D19: ☜ CR = CI / RI | F19: =IF(C19<=0.1,"∴O.K","∴N.G") -> ∴O.K
B20: N | C20: 3 | D20: 4 | E20: 5 | F20: 6 | G20: 7 | H20: 8 | I20: 9 | J20: 10
B21: RI | C21: 0.58 | D21: 0.9 | E21: 1.12 | F21: 1.24 | G21: 1.32 | H21: 1.41 | I21: 1.45 | J21: 1.51

Sheet 3g-PCM#5
A1: PERFORMANCE ATTRIBUTE RATING(PCM#5)
A2: ='1a-Performance'!A2 -> VE Title : | C2: ='1a-Performance'!B2 -> 포장두께
A3: A. Pairwise Comparison Matrices | G3: (설문자 : 시공전문가)
A5: 평 가 항 목 | C5: 1 | D5: 2 | E5: 3 | F5: 4 | G5: 5 | H5: 6 | I5: 7 | J5: 8 | L5: 행곱 | M5: N | N5: Eigen Vector | O5: Priority Vector | P5: 확정치(%) | Q5: 절대값
A6: 1 | B6: ='3a-Attribute Rating(A)'!B6 -> 시공성 | C6: 1 | D6: 1 | E6: 2 | F6: 2 | G6: 2 | H6: 3 | I6: 2 | J6: 3 | L6: =PRODUCT(C6:J6) -> 144 | M6: =IF($J$6<>"",8,(IF($I$6<>"",7,(IF($H$6<>"",6,5))))) -> 8 | N6: =L6^(1/M6) -> 1.8612097 | O6: =N6/$N$14 -> 0.21856255 | P6: =ROUND(O6,3) -> 0.219 | Q6: =ROUND(O6/MAX($O$6:$O$13)*9,0) -> 9
A7: 2 | B7: ='3a-Attribute Rating(A)'!B7 -> 유지관리성 | C7: =1/D6 -> 1 | D7: 1 | E7: 2 | F7: 1 | G7: 2 | H7: 2 | I7: 1 | J7: 2 | L7: =PRODUCT(C7:J7) -> 16 | M7: =IF($J$6<>"",8,(IF($I$6<>"",7,(IF($H$6<>"",6,5))))) -> 8 | N7: =L7^(1/M7) -> 1.4142136 | O7: =N7/$N$14 -> 0.16607162 | P7: =ROUND(O7,3) -> 0.166 | Q7: =ROUND(O7/MAX($O$6:$O$13)*9,0) -> 7
A8: 3 | B8: ='3a-Attribute Rating(A)'!B8 -> 내구성 | C8: =1/E6 -> 0.5 | D8: =1/E7 -> 0.5 | E8: 1 | F8: 1 | G8: 1 | H8: 2 | I8: 1 | J8: 2 | L8: =PRODUCT(C8:J8) -> 1 | M8: =IF($J$6<>"",8,(IF($I$6<>"",7,(IF($H$6<>"",6,5))))) -> 8 | N8: =L8^(1/M8) -> 1 | O8: =N8/$N$14 -> 0.11743037 | P8: =ROUND(O8,3) -> 0.117 | Q8: =ROUND(O8/MAX($O$6:$O$13)*9,0) -> 5
A9: 4 | B9: ='3a-Attribute Rating(A)'!B9 -> 이용편의성 | C9: =1/F6 -> 0.5 | D9: =1/F7 -> 1 | E9: =1/F8 -> 1 | F9: 1 | G9: 1 | H9: 1 | I9: 1 | J9: 1 | L9: =PRODUCT(C9:J9) -> 0.5 | M9: =IF($J$6<>"",8,(IF($I$6<>"",7,(IF($H$6<>"",6,5))))) -> 8 | N9: =L9^(1/M9) -> 0.91700404 | O9: =N9/$N$14 -> 0.10768413 | P9: =ROUND(O9,3) -> 0.108 | Q9: =ROUND(O9/MAX($O$6:$O$13)*9,0) -> 4
A10: 5 | B10: ='3a-Attribute Rating(A)'!B10 -> 친환경성 | C10: =1/G6 -> 0.5 | D10: =1/G7 -> 0.5 | E10: =1/G8 -> 1 | F10: =1/G9 -> 1 | G10: 1 | H10: 2 | I10: 1 | J10: 2 | L10: =PRODUCT(C10:J10) -> 1 | M10: =IF($J$6<>"",8,(IF($I$6<>"",7,(IF($H$6<>"",6,5))))) -> 8 | N10: =L10^(1/M10) -> 1 | O10: =N10/$N$14 -> 0.11743037 | P10: =ROUND(O10,3) -> 0.117 | Q10: =ROUND(O10/MAX($O$6:$O$13)*9,0) -> 5
A11: 6 | B11: ='3a-Attribute Rating(A)'!B11 -> 배수성 | C11: =1/H6 -> 0.33333333 | D11: =1/H7 -> 0.5 | E11: =1/H8 -> 0.5 | F11: =1/H9 -> 1 | G11: =1/H10 -> 0.5 | H11: 1 | I11: =1/2 -> 0.5 | J11: 1 | L11: =PRODUCT(C11:J11) -> 0.020833333 | M11: =IF($J$6<>"",8,(IF($I$6<>"",7,(IF($H$6<>"",6,5))))) -> 8 | N11: =L11^(1/M11) -> 0.61637476 | O11: =N11/$N$14 -> 0.072381117 | P11: =ROUND(O11,3) -> 0.072 | Q11: =ROUND(O11/MAX($O$6:$O$13)*9,0) -> 3
A12: 7 | B12: ='3a-Attribute Rating(A)'!B12 -> 교통안전성 | C12: =1/I6 -> 0.5 | D12: =1/I7 -> 1 | E12: =1/I8 -> 1 | F12: =1/I9 -> 1 | G12: =1/I10 -> 1 | H12: =1/I11 -> 2 | I12: 1 | J12: 2 | L12: =PRODUCT(C12:J12) -> 2 | M12: =IF($J$6<>"",8,(IF($I$6<>"",7,(IF($H$6<>"",6,5))))) -> 8 | N12: =L12^(1/M12) -> 1.0905077 | O12: =N12/$N$14 -> 0.12805873 | P12: =ROUND(O12,3) -> 0.128 | Q12: =ROUND(O12/MAX($O$6:$O$13)*9,0) -> 5
A13: 8 | B13: ='3a-Attribute Rating(A)'!B13 -> 민원성 | C13: =1/J6 -> 0.33333333 | D13: =1/J7 -> 0.5 | E13: =1/J8 -> 0.5 | F13: =1/J9 -> 1 | G13: =1/J10 -> 0.5 | H13: =1/J11 -> 1 | I13: =1/J12 -> 0.5 | J13: 1 | L13: =PRODUCT(C13:J13) -> 0.020833333 | M13: =IF($J$6<>"",8,(IF($I$6<>"",7,(IF($H$6<>"",6,5))))) -> 8 | N13: =L13^(1/M13) -> 0.61637476 | O13: =N13/$N$14 -> 0.072381117 | P13: =ROUND(O13,3) -> 0.072 | Q13: =ROUND(O13/MAX($O$6:$O$13)*9,0) -> 3
A14: 열(Column)합 | C14: =SUM(C6:C13) -> 4.6666667 | D14: =SUM(D6:D13) -> 6 | E14: =SUM(E6:E13) -> 9 | F14: =SUM(F6:F13) -> 9 | G14: =SUM(G6:G13) -> 9 | H14: =SUM(H6:H13) -> 14 | I14: =SUM(I6:I13) -> 8 | J14: =SUM(J6:J13) -> 14 | L14: SUM | N14: =SUM(N6:N13) -> 8.5156846 | O14: =SUM(O6:O13) -> 1 | P14: =SUM(P6:P13) -> 0.999
A16: B. Confidence Index(CI)
A17: B-1. λmax = | C17: =MMULT(C14:J14,O6:O13) -> 8.1504332 | D17: ☜ Pairwise Comparison Matrices의 열합행렬(1행×8열)과 Priority Veoctor(8행×1열)의 행렬곱
A18: B-2. CI = | C18: =(C17-M6)/(M6-1) -> 0.021490456 | D18: ☜ CI = (λmax - N) / (N-1)
A19: B-3. CR = | C19: =C18/(HLOOKUP(M6,C20:J21,2,TRUE)) -> 0.015241458 | D19: ☜ CR = CI / RI | F19: =IF(C19<=0.1,"∴O.K","∴N.G") -> ∴O.K
B20: N | C20: 3 | D20: 4 | E20: 5 | F20: 6 | G20: 7 | H20: 8 | I20: 9 | J20: 10
B21: RI | C21: 0.58 | D21: 0.9 | E21: 1.12 | F21: 1.24 | G21: 1.32 | H21: 1.41 | I21: 1.45 | J21: 1.51

Sheet 3h-Qustionnaire
A1: 선호도 설문조사
A2: ='1a-Performance'!A2:B2 -> VE Title : | B2: ='1a-Performance'!B2 -> 포장두께
A3: 속성평가(Objective Evaluation)
A4: 속성(Objective) | B4: 절 대 | D4: 매 우 | F4: 상 당 | H4: 약 간 | J4: 동 등 | L4: 약 간 | N4: 상 당 | P4: 매 우 | R4: 절 대 | S4: 속성(Objective)
A5: ='1a-Performance'!A5 -> 시공성 | B5: ⑨ | C5: ⑧ | D5: ⑦ | E5: ⑥ | F5: ⑤ | G5: ④ | H5: ③ | I5: ② | J5: ① | K5: ② | L5: ③ | M5: ④ | N5: ⑤ | O5: ⑥ | P5: ⑦ | Q5: ⑧ | R5: ⑨ | S5: ='1a-Performance'!A6 -> 유지관리성
B6: ⑨ | C6: ⑧ | D6: ⑦ | E6: ⑥ | F6: ⑤ | G6: ④ | H6: ③ | I6: ② | J6: ① | K6: ② | L6: ③ | M6: ④ | N6: ⑤ | O6: ⑥ | P6: ⑦ | Q6: ⑧ | R6: ⑨ | S6: ='1a-Performance'!A7 -> 내구성
B7: ⑨ | C7: ⑧ | D7: ⑦ | E7: ⑥ | F7: ⑤ | G7: ④ | H7: ③ | I7: ② | J7: ① | K7: ② | L7: ③ | M7: ④ | N7: ⑤ | O7: ⑥ | P7: ⑦ | Q7: ⑧ | R7: ⑨ | S7: ='1a-Performance'!A8 -> 이용편의성
B8: ⑨ | C8: ⑧ | D8: ⑦ | E8: ⑥ | F8: ⑤ | G8: ④ | H8: ③ | I8: ② | J8: ① | K8: ② | L8: ③ | M8: ④ | N8: ⑤ | O8: ⑥ | P8: ⑦ | Q8: ⑧ | R8: ⑨ | S8: ='1a-Performance'!A9 -> 친환경성
B9: ⑨ | C9: ⑧ | D9: ⑦ | E9: ⑥ | F9: ⑤ | G9: ④ | H9: ③ | I9: ② | J9: ① | K9: ② | L9: ③ | M9: ④ | N9: ⑤ | O9: ⑥ | P9: ⑦ | Q9: ⑧ | R9: ⑨ | S9: ='1a-Performance'!A10 -> 배수성
B10: ⑨ | C10: ⑧ | D10: ⑦ | E10: ⑥ | F10: ⑤ | G10: ④ | H10: ③ | I10: ② | J10: ① | K10: ② | L10: ③ | M10: ④ | N10: ⑤ | O10: ⑥ | P10: ⑦ | Q10: ⑧ | R10: ⑨ | S10: ='1a-Performance'!A11 -> 교통안전성
B11: ⑨ | C11: ⑧ | D11: ⑦ | E11: ⑥ | F11: ⑤ | G11: ④ | H11: ③ | I11: ② | J11: ① | K11: ② | L11: ③ | M11: ④ | N11: ⑤ | O11: ⑥ | P11: ⑦ | Q11: ⑧ | R11: ⑨ | S11: ='1a-Performance'!A12 -> 민원성
A12: ='1a-Performance'!A6 -> 유지관리성 | B12: ⑨ | C12: ⑧ | D12: ⑦ | E12: ⑥ | F12: ⑤ | G12: ④ | H12: ③ | I12: ② | J12: ① | K12: ② | L12: ③ | M12: ④ | N12: ⑤ | O12: ⑥ | P12: ⑦ | Q12: ⑧ | R12: ⑨ | S12: ='1a-Performance'!A7 -> 내구성
B13: ⑨ | C13: ⑧ | D13: ⑦ | E13: ⑥ | F13: ⑤ | G13: ④ | H13: ③ | I13: ② | J13: ① | K13: ② | L13: ③ | M13: ④ | N13: ⑤ | O13: ⑥ | P13: ⑦ | Q13: ⑧ | R13: ⑨ | S13: ='1a-Performance'!A8 -> 이용편의성
B14: ⑨ | C14: ⑧ | D14: ⑦ | E14: ⑥ | F14: ⑤ | G14: ④ | H14: ③ | I14: ② | J14: ① | K14: ② | L14: ③ | M14: ④ | N14: ⑤ | O14: ⑥ | P14: ⑦ | Q14: ⑧ | R14: ⑨ | S14: ='1a-Performance'!A9 -> 친환경성
B15: ⑨ | C15: ⑧ | D15: ⑦ | E15: ⑥ | F15: ⑤ | G15: ④ | H15: ③ | I15: ② | J15: ① | K15: ② | L15: ③ | M15: ④ | N15: ⑤ | O15: ⑥ | P15: ⑦ | Q15: ⑧ | R15: ⑨ | S15: ='1a-Performance'!A10 -> 배수성
B16: ⑨ | C16: ⑧ | D16: ⑦ | E16: ⑥ | F16: ⑤ | G16: ④ | H16: ③ | I16: ② | J16: ① | K16: ② | L16: ③ | M16: ④ | N16: ⑤ | O16: ⑥ | P16: ⑦ | Q16: ⑧ | R16: ⑨ | S16: ='1a-Performance'!A11 -> 교통안전성
B17: ⑨ | C17: ⑧ | D17: ⑦ | E17: ⑥ | F17: ⑤ | G17: ④ | H17: ③ | I17: ② | J17: ① | K17: ② | L17: ③ | M17: ④ | N17: ⑤ | O17: ⑥ | P17: ⑦ | Q17: ⑧ | R17: ⑨ | S17: ='1a-Performance'!A12 -> 민원성
A18: ='1a-Performance'!A7 -> 내구성 | B18: ⑨ | C18: ⑧ | D18: ⑦ | E18: ⑥ | F18: ⑤ | G18: ④ | H18: ③ | I18: ② | J18: ① | K18: ② | L18: ③ | M18: ④ | N18: ⑤ | O18: ⑥ | P18: ⑦ | Q18: ⑧ | R18: ⑨ | S18: ='1a-Performance'!A8 -> 이용편의성
B19: ⑨ | C19: ⑧ | D19: ⑦ | E19: ⑥ | F19: ⑤ | G19: ④ | H19: ③ | I19: ② | J19: ① | K19: ② | L19: ③ | M19: ④ | N19: ⑤ | O19: ⑥ | P19: ⑦ | Q19: ⑧ | R19: ⑨ | S19: ='1a-Performance'!A9 -> 친환경성
B20: ⑨ | C20: ⑧ | D20: ⑦ | E20: ⑥ | F20: ⑤ | G20: ④ | H20: ③ | I20: ② | J20: ① | K20: ② | L20: ③ | M20: ④ | N20: ⑤ | O20: ⑥ | P20: ⑦ | Q20: ⑧ | R20: ⑨ | S20: ='1a-Performance'!A10 -> 배수성
B21: ⑨ | C21: ⑧ | D21: ⑦ | E21: ⑥ | F21: ⑤ | G21: ④ | H21: ③ | I21: ② | J21: ① | K21: ② | L21: ③ | M21: ④ | N21: ⑤ | O21: ⑥ | P21: ⑦ | Q21: ⑧ | R21: ⑨ | S21: ='1a-Performance'!A11 -> 교통안전성
B22: ⑨ | C22: ⑧ | D22: ⑦ | E22: ⑥ | F22: ⑤ | G22: ④ | H22: ③ | I22: ② | J22: ① | K22: ② | L22: ③ | M22: ④ | N22: ⑤ | O22: ⑥ | P22: ⑦ | Q22: ⑧ | R22: ⑨ | S22: ='1a-Performance'!A12 -> 민원성
A23: ='1a-Performance'!A8 -> 이용편의성 | B23: ⑨ | C23: ⑧ | D23: ⑦ | E23: ⑥ | F23: ⑤ | G23: ④ | H23: ③ | I23: ② | J23: ① | K23: ② | L23: ③ | M23: ④ | N23: ⑤ | O23: ⑥ | P23: ⑦ | Q23: ⑧ | R23: ⑨ | S23: ='1a-Performance'!A9 -> 친환경성
B24: ⑨ | C24: ⑧ | D24: ⑦ | E24: ⑥ | F24: ⑤ | G24: ④ | H24: ③ | I24: ② | J24: ① | K24: ② | L24: ③ | M24: ④ | N24: ⑤ | O24: ⑥ | P24: ⑦ | Q24: ⑧ | R24: ⑨ | S24: ='1a-Performance'!A10 -> 배수성
B25: ⑨ | C25: ⑧ | D25: ⑦ | E25: ⑥ | F25: ⑤ | G25: ④ | H25: ③ | I25: ② | J25: ① | K25: ② | L25: ③ | M25: ④ | N25: ⑤ | O25: ⑥ | P25: ⑦ | Q25: ⑧ | R25: ⑨ | S25: ='1a-Performance'!A11 -> 교통안전성
B26: ⑨ | C26: ⑧ | D26: ⑦ | E26: ⑥ | F26: ⑤ | G26: ④ | H26: ③ | I26: ② | J26: ① | K26: ② | L26: ③ | M26: ④ | N26: ⑤ | O26: ⑥ | P26: ⑦ | Q26: ⑧ | R26: ⑨ | S26: ='1a-Performance'!A12 -> 민원성
A27: ='1a-Performance'!A9 -> 친환경성 | B27: ⑨ | C27: ⑧ | D27: ⑦ | E27: ⑥ | F27: ⑤ | G27: ④ | H27: ③ | I27: ② | J27: ① | K27: ② | L27: ③ | M27: ④ | N27: ⑤ | O27: ⑥ | P27: ⑦ | Q27: ⑧ | R27: ⑨ | S27: ='1a-Performance'!A10 -> 배수성
B28: ⑨ | C28: ⑧ | D28: ⑦ | E28: ⑥ | F28: ⑤ | G28: ④ | H28: ③ | I28: ② | J28: ① | K28: ② | L28: ③ | M28: ④ | N28: ⑤ | O28: ⑥ | P28: ⑦ | Q28: ⑧ | R28: ⑨ | S28: ='1a-Performance'!A11 -> 교통안전성
B29: ⑨ | C29: ⑧ | D29: ⑦ | E29: ⑥ | F29: ⑤ | G29: ④ | H29: ③ | I29: ② | J29: ① | K29: ② | L29: ③ | M29: ④ | N29: ⑤ | O29: ⑥ | P29: ⑦ | Q29: ⑧ | R29: ⑨ | S29: ='1a-Performance'!A12 -> 민원성
A30: ='1a-Performance'!A10 -> 배수성 | B30: ⑨ | C30: ⑧ | D30: ⑦ | E30: ⑥ | F30: ⑤ | G30: ④ | H30: ③ | I30: ② | J30: ① | K30: ② | L30: ③ | M30: ④ | N30: ⑤ | O30: ⑥ | P30: ⑦ | Q30: ⑧ | R30: ⑨ | S30: ='1a-Performance'!A11 -> 교통안전성
B31: ⑨ | C31: ⑧ | D31: ⑦ | E31: ⑥ | F31: ⑤ | G31: ④ | H31: ③ | I31: ② | J31: ① | K31: ② | L31: ③ | M31: ④ | N31: ⑤ | O31: ⑥ | P31: ⑦ | Q31: ⑧ | R31: ⑨ | S31: ='1a-Performance'!A12 -> 민원성
A32: ='1a-Performance'!A11 -> 교통안전성 | B32: ⑨ | C32: ⑧ | D32: ⑦ | E32: ⑥ | F32: ⑤ | G32: ④ | H32: ③ | I32: ② | J32: ① | K32: ② | L32: ③ | M32: ④ | N32: ⑤ | O32: ⑥ | P32: ⑦ | Q32: ⑧ | R32: ⑨ | S32: ='1a-Performance'!A12 -> 민원성
I34: ='1b-Sub-Performance'!B3 -> 시공성 | J34: 에 | K34: 따른 하위속성 평가
A35: 속성(Objective) | B35: 절 대 | D35: 매 우 | F35: 상 당 | H35: 약 간 | J35: 동 등 | L35: 약 간 | N35: 상 당 | P35: 매 우 | R35: 절 대 | S35: 속성(Objective)
A36: ='1b-Sub-Performance'!A5 -> 0 | B36: ⑨ | C36: ⑧ | D36: ⑦ | E36: ⑥ | F36: ⑤ | G36: ④ | H36: ③ | I36: ② | J36: ① | K36: ② | L36: ③ | M36: ④ | N36: ⑤ | O36: ⑥ | P36: ⑦ | Q36: ⑧ | R36: ⑨ | S36: ='1b-Sub-Performance'!A6 -> 0
B37: ⑨ | C37: ⑧ | D37: ⑦ | E37: ⑥ | F37: ⑤ | G37: ④ | H37: ③ | I37: ② | J37: ① | K37: ② | L37: ③ | M37: ④ | N37: ⑤ | O37: ⑥ | P37: ⑦ | Q37: ⑧ | R37: ⑨ | S37: ='1b-Sub-Performance'!A7 -> 0
B38: ⑨ | C38: ⑧ | D38: ⑦ | E38: ⑥ | F38: ⑤ | G38: ④ | H38: ③ | I38: ② | J38: ① | K38: ② | L38: ③ | M38: ④ | N38: ⑤ | O38: ⑥ | P38: ⑦ | Q38: ⑧ | R38: ⑨ | S38: ='1b-Sub-Performance'!#REF! -> #REF!
B39: ⑨ | C39: ⑧ | D39: ⑦ | E39: ⑥ | F39: ⑤ | G39: ④ | H39: ③ | I39: ② | J39: ① | K39: ② | L39: ③ | M39: ④ | N39: ⑤ | O39: ⑥ | P39: ⑦ | Q39: ⑧ | R39: ⑨ | S39: ='1b-Sub-Performance'!A8 -> 0
A40: ='1b-Sub-Performance'!A6 -> 0 | B40: ⑨ | C40: ⑧ | D40: ⑦ | E40: ⑥ | F40: ⑤ | G40: ④ | H40: ③ | I40: ② | J40: ① | K40: ② | L40: ③ | M40: ④ | N40: ⑤ | O40: ⑥ | P40: ⑦ | Q40: ⑧ | R40: ⑨ | S40: ='1b-Sub-Performance'!A7 -> 0
B41: ⑨ | C41: ⑧ | D41: ⑦ | E41: ⑥ | F41: ⑤ | G41: ④ | H41: ③ | I41: ② | J41: ① | K41: ② | L41: ③ | M41: ④ | N41: ⑤ | O41: ⑥ | P41: ⑦ | Q41: ⑧ | R41: ⑨ | S41: ='1b-Sub-Performance'!#REF! -> #REF!
...

Sheet 4a-Rating Rationale (1)
A1: Rating Rationale - Original Concept
A2: ='1a-Performance'!A2 -> VE Title : | B2: ='1a-Performance'!B2 -> 포장두께 | D2: 비교1안(PCC Slab 46cm)
A3: Performance | B3: Sub-Performance | C3: Rationale | D3: Rating
A4: ='3a-Attribute Rating(A)'!B6 -> 시공성 | D4: 5
A8: ='3a-Attribute Rating(A)'!B7 -> 유지관리성 | D8: 5
A12: ='3a-Attribute Rating(A)'!B8 -> 내구성 | D12: 5
A16: ='3a-Attribute Rating(A)'!B9 -> 이용편의성 | D16: 5
A20: ='3a-Attribute Rating(A)'!B10 -> 친환경성 | D20: 5
A24: ='3a-Attribute Rating(A)'!B11 -> 배수성 | D24: 5
A28: ='3a-Attribute Rating(A)'!B12 -> 교통안전성 | D28: 5
A32: ='3a-Attribute Rating(A)'!B13 -> 민원성 | D32: 5

Sheet 4b-Rating Rationale (2)
A1: Rating Rationale - Alt. Concept #1
A2: ='1a-Performance'!A2 -> VE Title : | B2: ='1a-Performance'!B2 -> 포장두께 | D2: 비교2안(PCC Slab 50cm)
A3: Performance | B3: Sub-Performance | C3: Rationale | D3: Rating
A4: ='3a-Attribute Rating(A)'!B6 -> 시공성 | D4: 4
A8: ='3a-Attribute Rating(A)'!B7 -> 유지관리성 | D8: 6
A12: ='3a-Attribute Rating(A)'!B8 -> 내구성 | D12: 10
A16: ='3a-Attribute Rating(A)'!B9 -> 이용편의성 | D16: 5
A20: ='3a-Attribute Rating(A)'!B10 -> 친환경성 | D20: 5
A24: ='3a-Attribute Rating(A)'!B11 -> 배수성 | D24: 5
A28: ='3a-Attribute Rating(A)'!B12 -> 교통안전성 | D28: 5
A32: ='3a-Attribute Rating(A)'!B13 -> 민원성 | D32: 6

Sheet 4c-Rating Rationale (3)
A1: Rating Rationale - Alt. Concept #2
A2: ='1a-Performance'!A2 -> VE Title : | B2: ='1a-Performance'!B2 -> 포장두께
A3: Performance | B3: Sub-Performance | C3: Rationale | D3: Rating
A4: ='3a-Attribute Rating(A)'!B6 -> 시공성 | C4: 평가사유
A8: ='3a-Attribute Rating(A)'!B7 -> 유지관리성 | C8: 평가사유
A12: ='3a-Attribute Rating(A)'!B8 -> 내구성 | C12: 평가사유
A16: ='3a-Attribute Rating(A)'!B9 -> 이용편의성 | C16: 평가사유
A20: ='3a-Attribute Rating(A)'!B10 -> 친환경성 | C20: 평가사유
A24: ='3a-Attribute Rating(A)'!B11 -> 배수성 | C24: 평가사유
A28: ='3a-Attribute Rating(A)'!B12 -> 교통안전성
A32: ='3a-Attribute Rating(A)'!B13 -> 민원성

Sheet 4d-Rating Rationale (4)
A1: Rating Rationale - Alt. Concept #3
A2: ='1a-Performance'!A2 -> VE Title : | B2: ='1a-Performance'!B2 -> 포장두께
A3: Performance | B3: Sub-Performance | C3: Rationale | D3: Rating
A4: ='3a-Attribute Rating(A)'!B6 -> 시공성 | C4: 평가사유
A8: ='3a-Attribute Rating(A)'!B7 -> 유지관리성 | C8: 평가사유
A12: ='3a-Attribute Rating(A)'!B8 -> 내구성 | C12: 평가사유
A16: ='3a-Attribute Rating(A)'!B9 -> 이용편의성 | C16: 평가사유
A20: ='3a-Attribute Rating(A)'!B10 -> 친환경성 | C20: 평가사유
A24: ='3a-Attribute Rating(A)'!B11 -> 배수성 | C24: 평가사유
A28: ='3a-Attribute Rating(A)'!B12 -> 교통안전성
A32: ='3a-Attribute Rating(A)'!B13 -> 민원성

Sheet 5a-Initial Cost (1)
A1: INITIAL COSTS
A2: ='1a-Performance'!A2 -> VE Title : | B2: ='1a-Performance'!B2 -> 포장두께
A3: CONSTRUCTION ELEMENT | C3: ORIGINAL CONCEPT | F3: ALTERNATIVE CONCEPT#1
C4: ='4a-Rating Rationale (1)'!D2 -> 비교1안(PCC Slab 46cm) | F4: ='4b-Rating Rationale (2)'!D2 -> 비교2안(PCC Slab 50cm)
A5: Description | B5: Unit | C5: Quantity | D5: Cost/Unit | E5: Total | F5: Quantity | G5: Cost/Unit | H5: Total
A6: Original Concept
A7: 직접공사비(억원) | B7: LS | C7: 1 | D7: =1432.8/1.24 -> 1155.4839 | E7: =ROUND(C7*D7,2) -> 1155.48
A8: 간접공사비(직접공사비×14%) | B8: LS | C8: 1 | D8: =D7*0.14 -> 161.76774 | E8: =ROUND(C8*D8,2) -> 161.77
A9: 관리비/이윤(직접공사비×10%) | B9: LS | C9: 1 | D9: =D7*0.1 -> 115.54839 | E9: =ROUND(C9*D9,2) -> 115.55
A10: 설계/감리비(공사비×3%) | B10: LS | C10: 1 | D10: =SUM(D7:D9)*0.03 -> 42.984 | E10: =ROUND(C10*D10,2) -> 42.98
A11: 측량/조사비(공사비×1%) | B11: LS | C11: 1 | D11: =SUM(D7:D9)*0.01 -> 14.328 | E11: =ROUND(C11*D11,2) -> 14.33
A12: 보상비(제외) | B12: LS | C12: 1 | E12: =ROUND(C12*D12,2) -> 0
A19: Alternative Concept #1
A20: 직접공사비(억원) | B20: LS | F20: 1 | G20: =(1432.8+25)/1.24 -> 1175.6452 | H20: =ROUND(F20*G20,2) -> 1175.65
A21: 간접공사비(직접공사비×14%) | B21: LS | F21: 1 | G21: =G20*0.14 -> 164.59032 | H21: =ROUND(F21*G21,2) -> 164.59
A22: 관리비/이윤(직접공사비×10%) | B22: LS | F22: 1 | G22: =G20*0.1 -> 117.56452 | H22: =ROUND(F22*G22,2) -> 117.56
A23: 설계/감리비(공사비×3%) | B23: LS | F23: 1 | G23: =SUM(G20:G22)*0.03 -> 43.734 | H23: =ROUND(F23*G23,2) -> 43.73
A24: 측량/조사비(공사비×1%) | B24: LS | F24: 1 | G24: =SUM(G20:G22)*0.01 -> 14.578 | H24: =ROUND(F24*G24,2) -> 14.58
A25: 보상비(제외) | B25: LS | F25: 1 | H25: =ROUND(F25*G25,2) -> 0
A32: SUB-TOTAL | E32: =SUM(E6:E31) -> 1490.11 | H32: =SUM(H6:H31) -> 1516.11
A33: PROJECT MARK-UPS | B33: 0 | E33: =E32*B33 -> 0 | H33: =H32*B33 -> 0
A34: TOTAL (hundred million won) | E34: =SUM(E32:E33) -> 1490.11 | H34: =SUM(H32:H33) -> 1516.11
A35: TOTAL (Rounded) | E35: =ROUND(E34,2) -> 1490.11 | H35: =ROUND(H34,2) -> 1516.11
G36: SAVINGS | H36: =E35-H35 -> -26

Sheet 5b-Initial Cost (2)
A1: INITIAL COSTS
A2: ='1a-Performance'!A2 -> VE Title : | B2: ='1a-Performance'!B2 -> 포장두께
A3: CONSTRUCTION ELEMENT | C3: ALTERNATIVE CONCEPT#2 | F3: ALTERNATIVE CONCEPT#3
C4: ='4c-Rating Rationale (3)'!D2 -> 0 | F4: ='4d-Rating Rationale (4)'!D2 -> 0
A5: Description | B5: Unit | C5: Quantity | D5: Cost/Unit | E5: Total | F5: Quantity | G5: Cost/Unit | H5: Total
A6: Alternative Concept #2
A7: 직접공사비 | B7: LS | C7: 1 | E7: =ROUND(C7*D7,2) -> 0
A8: 간접공사비(직접공사비×16.28%) | B8: LS | C8: 1 | D8: =D7*0.1628 -> 0 | E8: =ROUND(C8*D8,2) -> 0
A9: 관리비/이윤(직접공사비×12.60%) | B9: LS | C9: 1 | D9: =D7*0.126 -> 0 | E9: =ROUND(C9*D9,2) -> 0
A10: 설계/감리비(공사비×3%) | B10: LS | C10: 1 | D10: =SUM(D7:D9)*0.03 -> 0 | E10: =ROUND(C10*D10,2) -> 0
A11: 측량/조사비(공사비×1%) | B11: LS | C11: 1 | D11: =SUM(D7:D9)*0.01 -> 0 | E11: =ROUND(C11*D11,2) -> 0
A12: 보상비(제외) | B12: LS | C12: 1 | E12: =ROUND(C12*D12,2) -> 0
A19: Alternative Concept #3
A20: 직접공사비 | B20: LS | F20: 1 | H20: =ROUND(F20*G20,2) -> 0
A21: 간접공사비(직접공사비×16.28%) | B21: LS | F21: 1 | G21: =G20*0.1628 -> 0 | H21: =ROUND(F21*G21,2) -> 0
A22: 관리비/이윤(직접공사비×12.60%) | B22: LS | F22: 1 | G22: =G20*0.126 -> 0 | H22: =ROUND(F22*G22,2) -> 0
A23: 설계/감리비(공사비×3%) | B23: LS | F23: 1 | G23: =SUM(G20:G22)*0.03 -> 0 | H23: =ROUND(F23*G23,2) -> 0
A24: 측량/조사비(공사비×1%) | B24: LS | F24: 1 | G24: =SUM(G20:G22)*0.01 -> 0 | H24: =ROUND(F24*G24,2) -> 0
A25: 보상비(제외) | B25: LS | F25: 1 | H25: =ROUND(F25*G25,2) -> 0
A32: SUB-TOTAL | E32: =SUM(E6:E31) -> 0 | H32: =SUM(H6:H31) -> 0
A33: PROJECT MARK-UPS | B33: 0 | E33: =E32*B33 -> 0 | H33: =H32*B33 -> 0
A34: ='5a-Initial Cost (1)'!A34 -> TOTAL (hundred million won) | E34: =SUM(E32:E33) -> 0 | H34: =SUM(H32:H33) -> 0
A35: TOTAL (Rounded) | E35: =ROUND(E34,2) -> 0 | H35: =ROUND(H34,2) -> 0
D36: SAVINGS | E36: ='5a-Initial Cost (1)'!E35-E35 -> 1490.11 | G36: SAVINGS | H36: ='5a-Initial Cost (1)'!E35-H35 -> 1490.11

Sheet 5c-Life Cycle Cost (1)
A1: LIFE CYCLE COSTS
B2: ='1a-Performance'!A2 -> VE Title : | C2: ='1a-Performance'!B2 -> 포장두께
B3: Life Cycle Period | D3: 50 | E3: Years | H3: ORIGINAL | I3: ALT.#1
B4: Interest | D4: 5.5 | E4: % | H4: ='4a-Rating Rationale (1)'!D2 -> 비교1안(PCC Slab 46cm) | I4: ='4b-Rating Rationale (2)'!D2 -> 비교2안(PCC Slab 50cm)
A5: A. | B5: INITIAL COST | H5: ='5a-Initial Cost (1)'!E35 -> 1490.11 | I5: ='5a-Initial Cost (1)'!H35 -> 1516.11
B6: INITIAL COST SAVINGS: | I6: =H5-I5 -> -26
A7: B. | B7: ANNUAL COSTS
B8: 1. General Operations & Maintenance | H8: =600*0.005 -> 3 | I8: =625*0.005 -> 3.125
B9: 2. Energy
B10: 3. Supplies & Misc.
B11: Total Annual Costs: | H11: =SUM(H8:H10) -> 3 | I11: =SUM(I8:I10) -> 3.125
A12: Present Value Factor (P/A): | H12: =PV(D4*0.01,D3,-1) -> 16.931518 | I12: =PV(D4*0.01,D3,-1) -> 16.931518
A13: PRESENT VALUE OF ANNUAL COSTS: | H13: =H11*H12 -> 50.794554 | I13: =I11*I12 -> 52.910993 | K13: LCC 테이블1 | Q13: LCC 테이블2
A14: C. | B14: SINGLE EXPENDITURES | E14: Year | F14: Amount | G14: PV Factor | H14: Present Value | I14: Present Value | L14: ='4a-Rating Rationale (1)'!C1 -> 0 | M14: ='4b-Rating Rationale (2)'!C1 -> 0 | N14: ='4c-Rating Rationale (3)'!C1 -> 0 | O14: ='4d-Rating Rationale (4)'!C1 -> 0 | R14: =L14 -> 0 | S14: =M14 -> 0 | T14: =N14 -> 0 | U14: =O14 -> 0
B15: Original Concept | G15: =(1/(1+$D$4/100)^(E15)*1) -> 1 | K15: 초기투자비 | L15: =H5 -> 1490.11 | M15: =I5 -> 1516.11 | N15: ='5d-Life Cycle Cost (2)'!H5 -> 0 | O15: ='5b-Initial Cost (2)'!H35 -> 0 | Q15: 초기투자비 | R15: =L15/MIN($L$15:$N$15) -> #DIV/0! | S15: =M15/MIN($L$15:$N$15) -> #DIV/0! | T15: =N15/MIN($L$15:$N$15) -> #DIV/0! | U15: =O15/MIN($L$15:$N$15) -> #DIV/0!
B16: 1. 재포장비 | E16: 20 | F16: 600 | G16: =(1/(1+$D$4/100)^(E16)*1) -> 0.34272896 | H16: =F16*G16 -> 205.63738 | K16: 유지관리비 | L16: =H35 -> 306.27986 | M16: =I35 -> 94.091153 | N16: ='5d-Life Cycle Cost (2)'!H35 -> 0 | O16: ='5d-Life Cycle Cost (2)'!I13 -> 0 | Q16: 유지관리비 | R16: =L16/MIN($L$16:$N$16) -> #DIV/0! | S16: =M16/MIN($L$16:$N$16) -> #DIV/0! | T16: =N16/MIN($L$16:$N$16) -> #DIV/0! | U16: =O16/MIN($L$16:$N$16) -> #DIV/0!
E17: 40 | F17: =F16 -> 600 | G17: =(1/(1+$D$4/100)^(E17)*1) -> 0.11746314 | H17: =F17*G17 -> 70.477885 | K17: 해체폐기비 | L17: =$I$36 -> 0 | M17: ='5d-Life Cycle Cost (2)'!$H$36 -> 0 | N17: ='5d-Life Cycle Cost (2)'!$I$36 -> 0 | O17: =$H$36 -> 0 | Q17: 해체폐기비 | R17: =L17/MIN($L$17:$N$17) -> #DIV/0! | S17: =M17/MIN($L$17:$N$17) -> #DIV/0! | T17: =N17/MIN($L$17:$N$17) -> #DIV/0! | U17: =O17/MIN($L$17:$N$17) -> #DIV/0!
B18: 2. 잔존가치 | E18: 50 | F18: -300 | G18: =(1/(1+$D$4/100)^(E18)*1) -> 0.068766515 | H18: =F18*G18 -> -20.629955 | K18: LCC | L18: =SUM(L15:L17) -> 1796.3899 | M18: =SUM(M15:M17) -> 1610.2012 | N18: =SUM(N15:N17) -> 0 | O18: =SUM(O15:O17) -> 0 | Q18: LCC | R18: =L18/MIN($L$18:$N$18) -> #DIV/0! | S18: =M18/MIN($L$18:$N$18) -> #DIV/0! | T18: =N18/MIN($L$18:$N$18) -> #DIV/0! | U18: =O18/MIN($L$18:$N$18) -> #DIV/0!
G19: =(1/(1+$D$4/100)^(E19)*1) -> 1 | H19: =F19*G19 -> 0
G20: =(1/(1+$D$4/100)^(E20)*1) -> 1 | H20: =F20*G20 -> 0
G21: =(1/(1+$D$4/100)^(E21)*1) -> 1 | H21: =F21*G21 -> 0
G22: =(1/(1+$D$4/100)^(E22)*1) -> 1 | H22: =F22*G22 -> 0
G23: =(1/(1+$D$4/100)^(E23)*1) -> 1 | H23: =F23*G23 -> 0
B24: Alternative Concept #1 | G24: =(1/(1+$D$4/100)^(E24)*1) -> 1 | I24: =F24*G24 -> 0
B25: 1. 재포장비 | E25: 40 | F25: 625 | G25: =(1/(1+$D$4/100)^(E25)*1) -> 0.11746314 | I25: =F25*G25 -> 73.414464
G26: =(1/(1+$D$4/100)^(E26)*1) -> 1 | I26: =F26*G26 -> 0
B27: 2. 잔존가치 | E27: 50 | F27: =-625/40*30 -> -468.75 | G27: =(1/(1+$D$4/100)^(E27)*1) -> 0.068766515 | I27: =F27*G27 -> -32.234304
G28: =(1/(1+$D$4/100)^(E28)*1) -> 1 | I28: =F28*G28 -> 0
G29: =(1/(1+$D$4/100)^(E29)*1) -> 1 | I29: =F29*G29 -> 0
G30: =(1/(1+$D$4/100)^(E30)*1) -> 1 | I30: =F30*G30 -> 0
A34: PRESENT VALUE OF SINGLE EXPENDITURES: | H34: =SUM(H15:H33) -> 255.48531 | I34: =SUM(I15:I33) -> 41.18016
A35: D. | B35: TOTAL ANNUAL COSTS & SINGLE EXPENDITURES (B+C) | H35: =+H34+H13 -> 306.27986 | I35: =+I34+I13 -> 94.091153
A36: E. | B36: SALVAGE VALUE
A37: F. | B37: TOTAL PRESENT VALUE COST (A+D+E) | H37: =+H5+H35+H36 -> 1796.3899 | I37: =+I5+I35+I36 -> 1610.2012
A38: TOTAL LIFE CYCLE SAVINGS: | I38: =H37-I37 -> 186.18871

Sheet 5d-Life Cycle Cost (2)
A1: LIFE CYCLE COSTS
B2: ='1a-Performance'!A2 -> VE Title : | C2: ='1a-Performance'!B2 -> 포장두께
B3: Life Cycle Period | D3: ='5c-Life Cycle Cost (1)'!D3 -> 50 | E3: Years | H3: ALT.#2 | I3: ALT.#3
B4: Interest | D4: ='5c-Life Cycle Cost (1)'!D4 -> 5.5 | E4: % | H4: ='4c-Rating Rationale (3)'!D2 -> 0 | I4: ='4d-Rating Rationale (4)'!D2 -> 0
A5: A. | B5: INITIAL COST | H5: ='5b-Initial Cost (2)'!E35 -> 0 | I5: ='5b-Initial Cost (2)'!H35 -> 0
B6: INITIAL COST SAVINGS: | H6: ='5a-Initial Cost (1)'!E35-'5b-Initial Cost (2)'!E35 -> 1490.11 | I6: ='5c-Life Cycle Cost (1)'!H5-I5 -> 1490.11
A7: B. | B7: ANNUAL COSTS
B8: 1. General Operations & Maintenance
B9: 2. Energy
B10: 3. Supplies & Misc.
B11: Total Annual Costs: | H11: =SUM(H8:H10) -> 0 | I11: =SUM(I8:I10) -> 0
A12: Present Value Factor (P/A): | H12: =PV(D4*0.01,D3,-1) -> 16.931518 | I12: =PV(D4*0.01,D3,-1) -> 16.931518
A13: PRESENT VALUE OF ANNUAL COSTS: | H13: =H11*H12 -> 0 | I13: =I11*I12 -> 0
A14: C. | B14: SINGLE EXPENDITURES | E14: Year | F14: Amount | G14: PV Factor | H14: Present Value | I14: Present Value
B15: Alternative Concept #2 | G15: =(1/(1+$D$4/100)^(E15)*1) -> 1 | H15: =F15*G15 -> 0
B16: 1. 운영비 | G16: =(1/(1+$D$4/100)^(E16)*1) -> 1 | H16: =F16*G16 -> 0
B17: 2. 수선유지비 | G17: =(1/(1+$D$4/100)^(E17)*1) -> 1 | H17: =F17*G17 -> 0
B18: 3. 교량보수비 | G18: =(1/(1+$D$4/100)^(E18)*1) -> 1 | H18: =F18*G18 -> 0
B19: 4. 터널보수비 | G19: =(1/(1+$D$4/100)^(E19)*1) -> 1 | H19: =F19*G19 -> 0
